Workbook

Sheet Sheet1
I1: 2025
A2: Employee | B2: Grant | C2: Req'd Grant Hours/Month | D2: Actual Rate | E2: 2025 Annual/2080 | F2: Grant Rate | G2: Rate Burdened? | H2: Fringe | I2: January | J2: February | K2: March | L2: April | M2: May | N2: June | O2: July | P2: August | Q2: September | R2: October | S2: November | T2: December | U2: Allocation w/Actual Burdened | V2: Budget Amount | W2: Budget - Actual
A3: Daniel Longo | B3: Rising Tides | C3: 81.87 | D3: =90000/2080 -> 43.269231 | E3: =91374.4/2080 -> 43.93 | F3: 43.26 | G3: No | H3: 0.3 | I3: 65 | J3: 74 | K3: 82 | L3: 80 | M3: 86 | N3: 80 | O3: 110 | P3: 98 | Q3: 88 | R3: 153 | S3: 108 | T3: 91 | U3: =(E3*1.29)*(SUM(I3:T3)) -> 63186.715 | V3: =F3*(C3*12) -> 42500.354 | W3: =V3-U3 -> -20686.361
A4: Daniel Longo | B4: Hybrid | C4: =(4250/24)/2 -> 88.541667 | D4: =90000/2080 -> 43.269231 | E4: =91374.4/2080 -> 43.93 | F4: 50 | I4: 63 | J4: 28 | K4: 43 | L4: 34 | M4: 45 | N4: 47 | O4: 68 | P4: 62 | Q4: 88 | R4: 31 | S4: 52 | T4: 93 | U4: =(E4*1.29)*(SUM(I4:T4)) -> 37061.984 | V4: =F4*(C4*12) -> 53125 | W4: =V4-U4 -> 16063.016
A5: Daniel Longo | B5: Digital Engineering | D5: =90000/2080 -> 43.269231 | E5: =91374.4/2080 -> 43.93 | I5: 56 | J5: 58 | K5: 43 | L5: 61 | M5: 49 | N5: 41 | O5: 8 | P5: 0 | R5: 0 | S5: 0 | T5: 0 | U5: =(E5*1.29)*(SUM(I5:T5)) -> 17907.625 | V5: =F5*(C5*12) -> 0 | W5: =V5-U5 -> -17907.625
A6: Brittany Engel | B6: Drive AM | C6: 177 | D6: =77000/2080 -> 37.019231 | E6: =78307.73/2080 -> 37.647947 | F6: 63.83 | G6: No | I6: 100 | J6: 80 | K6: 100 | L6: 100 | M6: 100 | N6: 100 | O6: 100 | P6: 100 | Q6: 100 | R6: 100 | S6: 100 | T6: 100 | U6: =(E6*1.29)*(SUM(I6:T6)) -> 57307.705 | V6: =F6*(C6*12) -> 135574.92 | W6: =V6-U6 -> 78267.215
A7: Brittany Engel | B7: LTM | C7: 83.4 | D7: =77000/2080 -> 37.019231 | E7: =78307.73/2080 -> 37.647947 | F7: 52.55 | G7: Yes | I7: 80 | J7: 80 | K7: 80 | L7: 80 | M7: 56 | N7: 92 | O7: 80 | P7: 80 | Q7: 80 | R7: 80 | S7: 80 | T7: 80 | U7: =(E7*1.29)*(SUM(I7:T7)) -> 46040.427 | V7: =F7*(C7*12) -> 52592.04 | W7: =V7-U7 -> 6551.6125
A8: Dylan Negro | B8: Xjet | D8: =75000/2080 -> 36.057692 | E8: =76312.09/2080 -> 36.688505 | I8: 68 | J8: 38 | K8: 46 | L8: 49 | M8: 28 | N8: 68 | O8: 56 | P8: 42 | Q8: 21 | R8: 24 | S8: 0 | T8: 29 | U8: =(E8*1.29)*(SUM(I8:T8)) -> 22196.912 | V8: =F8*(C8*12) -> 0 | W8: =V8-U8 -> -22196.912
A9: Dylan Negro | B9: Rising Tides | C9: 34.67 | D9: =75000/2080 -> 36.057692 | E9: =76312.09/2080 -> 36.688505 | F9: 36.05 | G9: No | H9: 0.3 | I9: 20 | J9: 42 | K9: 42 | L9: 41 | M9: 68 | N9: 36 | O9: 64 | P9: 46 | Q9: 74 | R9: 76 | S9: 80 | T9: 75 | U9: =(E9*1.29)*(SUM(I9:T9)) -> 31425.906 | V9: =F9*(C9*12) -> 14998.242 | W9: =V9-U9 -> -16427.664
A10: Dylan Negro | B10: Drive AM | C10: 88 | D10: =75000/2080 -> 36.057692 | E10: =76312.09/2080 -> 36.688505 | F10: 63.83 | G10: Yes | I10: 88 | J10: 80 | K10: 80 | L10: 80 | M10: 80 | N10: 80 | O10: 80 | P10: 80 | Q10: 81 | R10: 84 | S10: 80 | T10: 80 | U10: =(E10*1.29)*(SUM(I10:T10)) -> 46050.311 | V10: =F10*(C10*12) -> 67404.48 | W10: =V10-U10 -> 21354.169
A11: Dean Jaric | B11: Drive AM | C11: 88 | D11: =77500/2080 -> 37.259615 | E11: =78492.76/2080 -> 37.736904 | F11: 63.83 | G11: Yes | I11: 59 | O11: 48 | U11: =(E11*1.29)*(SUM(I11:T11)) -> 5208.8248 | V11: =F11*(C11*12) -> 67404.48
A12: Dean Jaric | B12: Hybrid | C12: =C4 -> 88.541667 | D12: =77500/2080 -> 37.259615 | E12: =78492.76/2080 -> 37.736904 | F12: 50 | I12: 16 | O12: 15 | U12: =(E12*1.29)*(SUM(I12:T12)) -> 1509.0988 | V12: =F12*(C12*12) -> 53125
A13: Dean Jaric | B13: YBI | D13: =77500/2080 -> 37.259615 | E13: =78492.76/2080 -> 37.736904 | I13: 108 | O13: 121 | U13: =(E13*1.29)*(SUM(I13:T13)) -> 11147.859 | V13: =F13*(C13*12) -> 0
A14: Stephanie Gaffney | B14: Rising Tides | C14: 36.35 | D14: =155000/2080 -> 74.519231 | F14: 74.51 | G14: No | H14: 0.3 | U14: =(E14*1.29)*(SUM(I14:T14)) -> 0 | V14: =F14*(C14*12) -> 32501.262
A15: Stephanie Gaffney | B15: LTM | C15: 38.4 | D15: =155000/2080 -> 74.519231 | F15: 86.56 | G15: Yes | U15: =(E15*1.29)*(SUM(I15:T15)) -> 0 | V15: =F15*(C15*12) -> 39886.848
A16: Stephanie Gaffney | B16: Drive AM | C16: 14 | D16: =155000/2080 -> 74.519231 | F16: 92.08 | G16: Yes | U16: =(E16*1.29)*(SUM(I16:T16)) -> 0 | V16: =F16*(C16*12) -> 15469.44
A17: Stephanie Gaffney | B17: Rising Tides | C17: 36.35 | D17: =185000/2080 -> 88.942308 | F17: 74.51 | G17: No | H17: 0.3 | U17: =(E17*1.29)*(SUM(I17:T17)) -> 0 | V17: =F17*(C17*12) -> 32501.262
A18: Stephanie Gaffney | B18: LTM | C18: 38.4 | D18: =185000/2080 -> 88.942308 | F18: 86.56 | G18: Yes | U18: =(E18*1.29)*(SUM(I18:T18)) -> 0 | V18: =F18*(C18*12) -> 39886.848
A19: Stephanie Gaffney | B19: Drive AM | C19: 14 | D19: =185000/2080 -> 88.942308 | F19: 92.08 | G19: Yes | U19: =(E19*1.29)*(SUM(I19:T19)) -> 0 | V19: =F19*(C19*12) -> 15469.44
A20: Jessica Sprowl | B20: Rising Tides | C20: 33.43 | D20: =70000/2080 -> 33.653846 | E20: =71317.16/2080 -> 34.287096 | F20: 33.65 | G20: No | H20: 0.3 | I20: 7 | J20: 19 | K20: 19 | L20: 27 | M20: 28 | N20: =175/7 -> 25 | O20: =175/7 -> 25 | P20: =175/7 -> 25 | Q20: =175/7 -> 25 | R20: =175/7 -> 25 | S20: =175/7 -> 25 | T20: =175/7 -> 25 | U20: =(E20*1.29)*(SUM(I20:T20)) -> 12163.347 | V20: =F20*(C20*12) -> 13499.034 | W20: =V20-U20 -> 1335.6866
A21: Rory Kale | B21: Drive AM | C21: 44 | E21: =59850/2080 -> 28.774038 | F21: 34.53 | G21: Yes | I21: 42 | J21: 37 | K21: 44 | L21: 50 | M21: 50 | N21: 0 | O21: 0 | P21: 0 | Q21: 0 | R21: 0 | S21: 0 | T21: 0 | U21: =(E21*1.29)*(SUM(I21:T21)) -> 8277.4276 | V21: =F21*(C21*12) -> 18231.84 | W21: =V21-U21 -> 9954.4124
A22: Rory Kale | B22: Rising Tides | C22: 62.14 | D22: =52000/2080 -> 25 | E22: =59850/2080 -> 28.774038 | F22: 25.48 | G22: No | H22: 0.3 | I22: 8 | J22: 4 | K22: 4 | L22: 7 | M22: 0 | N22: 13 | O22: 4 | Q22: 0 | R22: 0 | S22: 0 | T22: 0 | U22: =(E22*1.29)*(SUM(I22:T22)) -> 1484.7404 | V22: =F22*(C22*12) -> 18999.926 | W22: =V22-U22 -> 17515.186

Sheet Time Breakdown
A1: 2025 | B1: Adj-AAMEN | C1: Adj-AM Other | D1: Adj-Apex | E1: Adj-CDBG | F1: Adj-Dig Eng M7 | G1: Adj-DLA | H1: Adj-Drive AM | I1: Adj-ESP | J1: Adj-Fundraising | K1: Adj-Hub | L1: Adj-Hybrid | M1: Adj-IIOT | N1: Adj-LTM | O1: Adj-MBAC | P1: Adj-NavAir | Q1: Adj-Rising Tides | R1: Adj-VGV | S1: Adj-Xjet | T1: Adj-Youth | U1: Adj-YBI | V1: Total
A2: Anderson | B2: =SUMIFS('Hours Log'!AD$2:AD$323,'Hours Log'!$A$2:$A$323,"="&'Time Breakdown'!$A2,'Hours Log'!$C$2:$C$323,"="&'Time Breakdown'!$A$1) -> 0 | C2: =SUMIFS('Hours Log'!AE$2:AE$323,'Hours Log'!$A$2:$A$323,"="&'Time Breakdown'!$A2,'Hours Log'!$C$2:$C$323,"="&'Time Breakdown'!$A$1) -> 0 | D2: =SUMIFS('Hours Log'!AF$2:AF$323,'Hours Log'!$A$2:$A$323,"="&'Time Breakdown'!$A2,'Hours Log'!$C$2:$C$323,"="&'Time Breakdown'!$A$1) -> 0 | E2: =SUMIFS('Hours Log'!AG$2:AG$323,'Hours Log'!$A$2:$A$323,"="&'Time Breakdown'!$A2,'Hours Log'!$C$2:$C$323,"="&'Time Breakdown'!$A$1) -> 0 | F2: =SUMIFS('Hours Log'!AH$2:AH$323,'Hours Log'!$A$2:$A$323,"="&'Time Breakdown'!$A2,'Hours Log'!$C$2:$C$323,"="&'Time Breakdown'!$A$1) -> 0 | G2: =SUMIFS('Hours Log'!AI$2:AI$323,'Hours Log'!$A$2:$A$323,"="&'Time Breakdown'!$A2,'Hours Log'!$C$2:$C$323,"="&'Time Breakdown'!$A$1) -> 0 | H2: =SUMIFS('Hours Log'!AJ$2:AJ$323,'Hours Log'!$A$2:$A$323,"="&'Time Breakdown'!$A2,'Hours Log'!$C$2:$C$323,"="&'Time Breakdown'!$A$1) -> 0 | I2: =SUMIFS('Hours Log'!AK$2:AK$323,'Hours Log'!$A$2:$A$323,"="&'Time Breakdown'!$A2,'Hours Log'!$C$2:$C$323,"="&'Time Breakdown'!$A$1) -> 0 | ... U2: =SUMIFS('Hours Log'!AW$2:AW$323,'Hours Log'!$A$2:$A$323,"="&'Time Breakdown'!$A2,'Hours Log'!$C$2:$C$323,"="&'Time Breakdown'!$A$1) -> 0 | V2: =SUM(B2:U2) -> 100
A3: Baxter | B3: =SUMIFS('Hours Log'!AD$2:AD$323,'Hours Log'!$A$2:$A$323,"="&'Time Breakdown'!$A3,'Hours Log'!$C$2:$C$323,"="&'Time Breakdown'!$A$1) -> 0 | C3: =SUMIFS('Hours Log'!AE$2:AE$323,'Hours Log'!$A$2:$A$323,"="&'Time Breakdown'!$A3,'Hours Log'!$C$2:$C$323,"="&'Time Breakdown'!$A$1) -> 0 | D3: =SUMIFS('Hours Log'!AF$2:AF$323,'Hours Log'!$A$2:$A$323,"="&'Time Breakdown'!$A3,'Hours Log'!$C$2:$C$323,"="&'Time Breakdown'!$A$1) -> 0 | E3: =SUMIFS('Hours Log'!AG$2:AG$323,'Hours Log'!$A$2:$A$323,"="&'Time Breakdown'!$A3,'Hours Log'!$C$2:$C$323,"="&'Time Breakdown'!$A$1) -> 0 | F3: =SUMIFS('Hours Log'!AH$2:AH$323,'Hours Log'!$A$2:$A$323,"="&'Time Breakdown'!$A3,'Hours Log'!$C$2:$C$323,"="&'Time Breakdown'!$A$1) -> 0 | G3: =SUMIFS('Hours Log'!AI$2:AI$323,'Hours Log'!$A$2:$A$323,"="&'Time Breakdown'!$A3,'Hours Log'!$C$2:$C$323,"="&'Time Breakdown'!$A$1) -> 0 | H3: =SUMIFS('Hours Log'!AJ$2:AJ$323,'Hours Log'!$A$2:$A$323,"="&'Time Breakdown'!$A3,'Hours Log'!$C$2:$C$323,"="&'Time Breakdown'!$A$1) -> 0 | I3: =SUMIFS('Hours Log'!AK$2:AK$323,'Hours Log'!$A$2:$A$323,"="&'Time Breakdown'!$A3,'Hours Log'!$C$2:$C$323,"="&'Time Breakdown'!$A$1) -> 100 | ... U3: =SUMIFS('Hours Log'!AW$2:AW$323,'Hours Log'!$A$2:$A$323,"="&'Time Breakdown'!$A3,'Hours Log'!$C$2:$C$323,"="&'Time Breakdown'!$A$1) -> 0 | V3: =SUM(B3:U3) -> 100
A4: Bixel | B4: =SUMIFS('Hours Log'!AD$2:AD$323,'Hours Log'!$A$2:$A$323,"="&'Time Breakdown'!$A4,'Hours Log'!$C$2:$C$323,"="&'Time Breakdown'!$A$1) -> 0 | C4: =SUMIFS('Hours Log'!AE$2:AE$323,'Hours Log'!$A$2:$A$323,"="&'Time Breakdown'!$A4,'Hours Log'!$C$2:$C$323,"="&'Time Breakdown'!$A$1) -> 0 | D4: =SUMIFS('Hours Log'!AF$2:AF$323,'Hours Log'!$A$2:$A$323,"="&'Time Breakdown'!$A4,'Hours Log'!$C$2:$C$323,"="&'Time Breakdown'!$A$1) -> 0 | E4: =SUMIFS('Hours Log'!AG$2:AG$323,'Hours Log'!$A$2:$A$323,"="&'Time Breakdown'!$A4,'Hours Log'!$C$2:$C$323,"="&'Time Breakdown'!$A$1) -> 0 | F4: =SUMIFS('Hours Log'!AH$2:AH$323,'Hours Log'!$A$2:$A$323,"="&'Time Breakdown'!$A4,'Hours Log'!$C$2:$C$323,"="&'Time Breakdown'!$A$1) -> 0 | G4: =SUMIFS('Hours Log'!AI$2:AI$323,'Hours Log'!$A$2:$A$323,"="&'Time Breakdown'!$A4,'Hours Log'!$C$2:$C$323,"="&'Time Breakdown'!$A$1) -> 0 | H4: =SUMIFS('Hours Log'!AJ$2:AJ$323,'Hours Log'!$A$2:$A$323,"="&'Time Breakdown'!$A4,'Hours Log'!$C$2:$C$323,"="&'Time Breakdown'!$A$1) -> 0 | I4: =SUMIFS('Hours Log'!AK$2:AK$323,'Hours Log'!$A$2:$A$323,"="&'Time Breakdown'!$A4,'Hours Log'!$C$2:$C$323,"="&'Time Breakdown'!$A$1) -> 100 | ... U4: =SUMIFS('Hours Log'!AW$2:AW$323,'Hours Log'!$A$2:$A$323,"="&'Time Breakdown'!$A4,'Hours Log'!$C$2:$C$323,"="&'Time Breakdown'!$A$1) -> 0 | V4: =SUM(B4:U4) -> 100
A5: Byers | B5: =SUMIFS('Hours Log'!AD$2:AD$323,'Hours Log'!$A$2:$A$323,"="&'Time Breakdown'!$A5,'Hours Log'!$C$2:$C$323,"="&'Time Breakdown'!$A$1) -> 0 | C5: =SUMIFS('Hours Log'!AE$2:AE$323,'Hours Log'!$A$2:$A$323,"="&'Time Breakdown'!$A5,'Hours Log'!$C$2:$C$323,"="&'Time Breakdown'!$A$1) -> 0 | D5: =SUMIFS('Hours Log'!AF$2:AF$323,'Hours Log'!$A$2:$A$323,"="&'Time Breakdown'!$A5,'Hours Log'!$C$2:$C$323,"="&'Time Breakdown'!$A$1) -> 0 | E5: =SUMIFS('Hours Log'!AG$2:AG$323,'Hours Log'!$A$2:$A$323,"="&'Time Breakdown'!$A5,'Hours Log'!$C$2:$C$323,"="&'Time Breakdown'!$A$1) -> 0 | F5: =SUMIFS('Hours Log'!AH$2:AH$323,'Hours Log'!$A$2:$A$323,"="&'Time Breakdown'!$A5,'Hours Log'!$C$2:$C$323,"="&'Time Breakdown'!$A$1) -> 0 | G5: =SUMIFS('Hours Log'!AI$2:AI$323,'Hours Log'!$A$2:$A$323,"="&'Time Breakdown'!$A5,'Hours Log'!$C$2:$C$323,"="&'Time Breakdown'!$A$1) -> 0 | H5: =SUMIFS('Hours Log'!AJ$2:AJ$323,'Hours Log'!$A$2:$A$323,"="&'Time Breakdown'!$A5,'Hours Log'!$C$2:$C$323,"="&'Time Breakdown'!$A$1) -> 0 | I5: =SUMIFS('Hours Log'!AK$2:AK$323,'Hours Log'!$A$2:$A$323,"="&'Time Breakdown'!$A5,'Hours Log'!$C$2:$C$323,"="&'Time Breakdown'!$A$1) -> 0 | ... U5: =SUMIFS('Hours Log'!AW$2:AW$323,'Hours Log'!$A$2:$A$323,"="&'Time Breakdown'!$A5,'Hours Log'!$C$2:$C$323,"="&'Time Breakdown'!$A$1) -> 0 | V5: =SUM(B5:U5) -> 100
A6: Canton | B6: =SUMIFS('Hours Log'!AD$2:AD$323,'Hours Log'!$A$2:$A$323,"="&'Time Breakdown'!$A6,'Hours Log'!$C$2:$C$323,"="&'Time Breakdown'!$A$1) -> 0 | C6: =SUMIFS('Hours Log'!AE$2:AE$323,'Hours Log'!$A$2:$A$323,"="&'Time Breakdown'!$A6,'Hours Log'!$C$2:$C$323,"="&'Time Breakdown'!$A$1) -> 0 | D6: =SUMIFS('Hours Log'!AF$2:AF$323,'Hours Log'!$A$2:$A$323,"="&'Time Breakdown'!$A6,'Hours Log'!$C$2:$C$323,"="&'Time Breakdown'!$A$1) -> 0 | E6: =SUMIFS('Hours Log'!AG$2:AG$323,'Hours Log'!$A$2:$A$323,"="&'Time Breakdown'!$A6,'Hours Log'!$C$2:$C$323,"="&'Time Breakdown'!$A$1) -> 0 | F6: =SUMIFS('Hours Log'!AH$2:AH$323,'Hours Log'!$A$2:$A$323,"="&'Time Breakdown'!$A6,'Hours Log'!$C$2:$C$323,"="&'Time Breakdown'!$A$1) -> 0 | G6: =SUMIFS('Hours Log'!AI$2:AI$323,'Hours Log'!$A$2:$A$323,"="&'Time Breakdown'!$A6,'Hours Log'!$C$2:$C$323,"="&'Time Breakdown'!$A$1) -> 0 | H6: =SUMIFS('Hours Log'!AJ$2:AJ$323,'Hours Log'!$A$2:$A$323,"="&'Time Breakdown'!$A6,'Hours Log'!$C$2:$C$323,"="&'Time Breakdown'!$A$1) -> 0 | I6: =SUMIFS('Hours Log'!AK$2:AK$323,'Hours Log'!$A$2:$A$323,"="&'Time Breakdown'!$A6,'Hours Log'!$C$2:$C$323,"="&'Time Breakdown'!$A$1) -> 100 | ... U6: =SUMIFS('Hours Log'!AW$2:AW$323,'Hours Log'!$A$2:$A$323,"="&'Time Breakdown'!$A6,'Hours Log'!$C$2:$C$323,"="&'Time Breakdown'!$A$1) -> 0 | V6: =SUM(B6:U6) -> 100
A7: Chunn | B7: =SUMIFS('Hours Log'!AD$2:AD$323,'Hours Log'!$A$2:$A$323,"="&'Time Breakdown'!$A7,'Hours Log'!$C$2:$C$323,"="&'Time Breakdown'!$A$1) -> 0 | C7: =SUMIFS('Hours Log'!AE$2:AE$323,'Hours Log'!$A$2:$A$323,"="&'Time Breakdown'!$A7,'Hours Log'!$C$2:$C$323,"="&'Time Breakdown'!$A$1) -> 0 | D7: =SUMIFS('Hours Log'!AF$2:AF$323,'Hours Log'!$A$2:$A$323,"="&'Time Breakdown'!$A7,'Hours Log'!$C$2:$C$323,"="&'Time Breakdown'!$A$1) -> 0 | E7: =SUMIFS('Hours Log'!AG$2:AG$323,'Hours Log'!$A$2:$A$323,"="&'Time Breakdown'!$A7,'Hours Log'!$C$2:$C$323,"="&'Time Breakdown'!$A$1) -> 0 | F7: =SUMIFS('Hours Log'!AH$2:AH$323,'Hours Log'!$A$2:$A$323,"="&'Time Breakdown'!$A7,'Hours Log'!$C$2:$C$323,"="&'Time Breakdown'!$A$1) -> 0 | G7: =SUMIFS('Hours Log'!AI$2:AI$323,'Hours Log'!$A$2:$A$323,"="&'Time Breakdown'!$A7,'Hours Log'!$C$2:$C$323,"="&'Time Breakdown'!$A$1) -> 0 | H7: =SUMIFS('Hours Log'!AJ$2:AJ$323,'Hours Log'!$A$2:$A$323,"="&'Time Breakdown'!$A7,'Hours Log'!$C$2:$C$323,"="&'Time Breakdown'!$A$1) -> 0 | I7: =SUMIFS('Hours Log'!AK$2:AK$323,'Hours Log'!$A$2:$A$323,"="&'Time Breakdown'!$A7,'Hours Log'!$C$2:$C$323,"="&'Time Breakdown'!$A$1) -> 100 | ... U7: =SUMIFS('Hours Log'!AW$2:AW$323,'Hours Log'!$A$2:$A$323,"="&'Time Breakdown'!$A7,'Hours Log'!$C$2:$C$323,"="&'Time Breakdown'!$A$1) -> 0 | V7: =SUM(B7:U7) -> 100
A8: Davis | B8: =SUMIFS('Hours Log'!AD$2:AD$323,'Hours Log'!$A$2:$A$323,"="&'Time Breakdown'!$A8,'Hours Log'!$C$2:$C$323,"="&'Time Breakdown'!$A$1) -> 0 | C8: =SUMIFS('Hours Log'!AE$2:AE$323,'Hours Log'!$A$2:$A$323,"="&'Time Breakdown'!$A8,'Hours Log'!$C$2:$C$323,"="&'Time Breakdown'!$A$1) -> 0 | D8: =SUMIFS('Hours Log'!AF$2:AF$323,'Hours Log'!$A$2:$A$323,"="&'Time Breakdown'!$A8,'Hours Log'!$C$2:$C$323,"="&'Time Breakdown'!$A$1) -> 0 | E8: =SUMIFS('Hours Log'!AG$2:AG$323,'Hours Log'!$A$2:$A$323,"="&'Time Breakdown'!$A8,'Hours Log'!$C$2:$C$323,"="&'Time Breakdown'!$A$1) -> 0 | F8: =SUMIFS('Hours Log'!AH$2:AH$323,'Hours Log'!$A$2:$A$323,"="&'Time Breakdown'!$A8,'Hours Log'!$C$2:$C$323,"="&'Time Breakdown'!$A$1) -> 0 | G8: =SUMIFS('Hours Log'!AI$2:AI$323,'Hours Log'!$A$2:$A$323,"="&'Time Breakdown'!$A8,'Hours Log'!$C$2:$C$323,"="&'Time Breakdown'!$A$1) -> 0 | H8: =SUMIFS('Hours Log'!AJ$2:AJ$323,'Hours Log'!$A$2:$A$323,"="&'Time Breakdown'!$A8,'Hours Log'!$C$2:$C$323,"="&'Time Breakdown'!$A$1) -> 0 | I8: =SUMIFS('Hours Log'!AK$2:AK$323,'Hours Log'!$A$2:$A$323,"="&'Time Breakdown'!$A8,'Hours Log'!$C$2:$C$323,"="&'Time Breakdown'!$A$1) -> 0 | ... U8: =SUMIFS('Hours Log'!AW$2:AW$323,'Hours Log'!$A$2:$A$323,"="&'Time Breakdown'!$A8,'Hours Log'!$C$2:$C$323,"="&'Time Breakdown'!$A$1) -> 0 | V8: =SUM(B8:U8) -> 100
A9: Dively | B9: =SUMIFS('Hours Log'!AD$2:AD$323,'Hours Log'!$A$2:$A$323,"="&'Time Breakdown'!$A9,'Hours Log'!$C$2:$C$323,"="&'Time Breakdown'!$A$1) -> 0 | C9: =SUMIFS('Hours Log'!AE$2:AE$323,'Hours Log'!$A$2:$A$323,"="&'Time Breakdown'!$A9,'Hours Log'!$C$2:$C$323,"="&'Time Breakdown'!$A$1) -> 0 | D9: =SUMIFS('Hours Log'!AF$2:AF$323,'Hours Log'!$A$2:$A$323,"="&'Time Breakdown'!$A9,'Hours Log'!$C$2:$C$323,"="&'Time Breakdown'!$A$1) -> 0 | E9: =SUMIFS('Hours Log'!AG$2:AG$323,'Hours Log'!$A$2:$A$323,"="&'Time Breakdown'!$A9,'Hours Log'!$C$2:$C$323,"="&'Time Breakdown'!$A$1) -> 0 | F9: =SUMIFS('Hours Log'!AH$2:AH$323,'Hours Log'!$A$2:$A$323,"="&'Time Breakdown'!$A9,'Hours Log'!$C$2:$C$323,"="&'Time Breakdown'!$A$1) -> 0 | G9: =SUMIFS('Hours Log'!AI$2:AI$323,'Hours Log'!$A$2:$A$323,"="&'Time Breakdown'!$A9,'Hours Log'!$C$2:$C$323,"="&'Time Breakdown'!$A$1) -> 0 | H9: =SUMIFS('Hours Log'!AJ$2:AJ$323,'Hours Log'!$A$2:$A$323,"="&'Time Breakdown'!$A9,'Hours Log'!$C$2:$C$323,"="&'Time Breakdown'!$A$1) -> 0 | I9: =SUMIFS('Hours Log'!AK$2:AK$323,'Hours Log'!$A$2:$A$323,"="&'Time Breakdown'!$A9,'Hours Log'!$C$2:$C$323,"="&'Time Breakdown'!$A$1) -> 100 | ... U9: =SUMIFS('Hours Log'!AW$2:AW$323,'Hours Log'!$A$2:$A$323,"="&'Time Breakdown'!$A9,'Hours Log'!$C$2:$C$323,"="&'Time Breakdown'!$A$1) -> 0 | V9: =SUM(B9:U9) -> 100
A10: Dwyer | B10: =SUMIFS('Hours Log'!AD$2:AD$323,'Hours Log'!$A$2:$A$323,"="&'Time Breakdown'!$A10,'Hours Log'!$C$2:$C$323,"="&'Time Breakdown'!$A$1) -> 0 | C10: =SUMIFS('Hours Log'!AE$2:AE$323,'Hours Log'!$A$2:$A$323,"="&'Time Breakdown'!$A10,'Hours Log'!$C$2:$C$323,"="&'Time Breakdown'!$A$1) -> 0 | D10: =SUMIFS('Hours Log'!AF$2:AF$323,'Hours Log'!$A$2:$A$323,"="&'Time Breakdown'!$A10,'Hours Log'!$C$2:$C$323,"="&'Time Breakdown'!$A$1) -> 0 | E10: =SUMIFS('Hours Log'!AG$2:AG$323,'Hours Log'!$A$2:$A$323,"="&'Time Breakdown'!$A10,'Hours Log'!$C$2:$C$323,"="&'Time Breakdown'!$A$1) -> 0 | F10: =SUMIFS('Hours Log'!AH$2:AH$323,'Hours Log'!$A$2:$A$323,"="&'Time Breakdown'!$A10,'Hours Log'!$C$2:$C$323,"="&'Time Breakdown'!$A$1) -> 0 | G10: =SUMIFS('Hours Log'!AI$2:AI$323,'Hours Log'!$A$2:$A$323,"="&'Time Breakdown'!$A10,'Hours Log'!$C$2:$C$323,"="&'Time Breakdown'!$A$1) -> 0 | H10: =SUMIFS('Hours Log'!AJ$2:AJ$323,'Hours Log'!$A$2:$A$323,"="&'Time Breakdown'!$A10,'Hours Log'!$C$2:$C$323,"="&'Time Breakdown'!$A$1) -> 0 | I10: =SUMIFS('Hours Log'!AK$2:AK$323,'Hours Log'!$A$2:$A$323,"="&'Time Breakdown'!$A10,'Hours Log'!$C$2:$C$323,"="&'Time Breakdown'!$A$1) -> 100 | ... U10: =SUMIFS('Hours Log'!AW$2:AW$323,'Hours Log'!$A$2:$A$323,"="&'Time Breakdown'!$A10,'Hours Log'!$C$2:$C$323,"="&'Time Breakdown'!$A$1) -> 0 | V10: =SUM(B10:U10) -> 100
A11: Engel | B11: =SUMIFS('Hours Log'!AD$2:AD$323,'Hours Log'!$A$2:$A$323,"="&'Time Breakdown'!$A11,'Hours Log'!$C$2:$C$323,"="&'Time Breakdown'!$A$1) -> 0 | C11: =SUMIFS('Hours Log'!AE$2:AE$323,'Hours Log'!$A$2:$A$323,"="&'Time Breakdown'!$A11,'Hours Log'!$C$2:$C$323,"="&'Time Breakdown'!$A$1) -> 0 | D11: =SUMIFS('Hours Log'!AF$2:AF$323,'Hours Log'!$A$2:$A$323,"="&'Time Breakdown'!$A11,'Hours Log'!$C$2:$C$323,"="&'Time Breakdown'!$A$1) -> 0 | E11: =SUMIFS('Hours Log'!AG$2:AG$323,'Hours Log'!$A$2:$A$323,"="&'Time Breakdown'!$A11,'Hours Log'!$C$2:$C$323,"="&'Time Breakdown'!$A$1) -> 0 | F11: =SUMIFS('Hours Log'!AH$2:AH$323,'Hours Log'!$A$2:$A$323,"="&'Time Breakdown'!$A11,'Hours Log'!$C$2:$C$323,"="&'Time Breakdown'!$A$1) -> 0 | G11: =SUMIFS('Hours Log'!AI$2:AI$323,'Hours Log'!$A$2:$A$323,"="&'Time Breakdown'!$A11,'Hours Log'!$C$2:$C$323,"="&'Time Breakdown'!$A$1) -> 0 | H11: =SUMIFS('Hours Log'!AJ$2:AJ$323,'Hours Log'!$A$2:$A$323,"="&'Time Breakdown'!$A11,'Hours Log'!$C$2:$C$323,"="&'Time Breakdown'!$A$1) -> 1160.3205 | I11: =SUMIFS('Hours Log'!AK$2:AK$323,'Hours Log'!$A$2:$A$323,"="&'Time Breakdown'!$A11,'Hours Log'!$C$2:$C$323,"="&'Time Breakdown'!$A$1) -> 0 | ... U11: =SUMIFS('Hours Log'!AW$2:AW$323,'Hours Log'!$A$2:$A$323,"="&'Time Breakdown'!$A11,'Hours Log'!$C$2:$C$323,"="&'Time Breakdown'!$A$1) -> 0 | V11: =SUM(B11:U11) -> 2088
A12: Ewing | B12: =SUMIFS('Hours Log'!AD$2:AD$323,'Hours Log'!$A$2:$A$323,"="&'Time Breakdown'!$A12,'Hours Log'!$C$2:$C$323,"="&'Time Breakdown'!$A$1) -> 0 | C12: =SUMIFS('Hours Log'!AE$2:AE$323,'Hours Log'!$A$2:$A$323,"="&'Time Breakdown'!$A12,'Hours Log'!$C$2:$C$323,"="&'Time Breakdown'!$A$1) -> 0 | D12: =SUMIFS('Hours Log'!AF$2:AF$323,'Hours Log'!$A$2:$A$323,"="&'Time Breakdown'!$A12,'Hours Log'!$C$2:$C$323,"="&'Time Breakdown'!$A$1) -> 0 | E12: =SUMIFS('Hours Log'!AG$2:AG$323,'Hours Log'!$A$2:$A$323,"="&'Time Breakdown'!$A12,'Hours Log'!$C$2:$C$323,"="&'Time Breakdown'!$A$1) -> 0 | F12: =SUMIFS('Hours Log'!AH$2:AH$323,'Hours Log'!$A$2:$A$323,"="&'Time Breakdown'!$A12,'Hours Log'!$C$2:$C$323,"="&'Time Breakdown'!$A$1) -> 0 | G12: =SUMIFS('Hours Log'!AI$2:AI$323,'Hours Log'!$A$2:$A$323,"="&'Time Breakdown'!$A12,'Hours Log'!$C$2:$C$323,"="&'Time Breakdown'!$A$1) -> 0 | H12: =SUMIFS('Hours Log'!AJ$2:AJ$323,'Hours Log'!$A$2:$A$323,"="&'Time Breakdown'!$A12,'Hours Log'!$C$2:$C$323,"="&'Time Breakdown'!$A$1) -> 0 | I12: =SUMIFS('Hours Log'!AK$2:AK$323,'Hours Log'!$A$2:$A$323,"="&'Time Breakdown'!$A12,'Hours Log'!$C$2:$C$323,"="&'Time Breakdown'!$A$1) -> 951.59721 | ... U12: =SUMIFS('Hours Log'!AW$2:AW$323,'Hours Log'!$A$2:$A$323,"="&'Time Breakdown'!$A12,'Hours Log'!$C$2:$C$323,"="&'Time Breakdown'!$A$1) -> 282.91665 | V12: =SUM(B12:U12) -> 2088
A13: Fiffick | B13: =SUMIFS('Hours Log'!AD$2:AD$323,'Hours Log'!$A$2:$A$323,"="&'Time Breakdown'!$A13,'Hours Log'!$C$2:$C$323,"="&'Time Breakdown'!$A$1) -> 0 | C13: =SUMIFS('Hours Log'!AE$2:AE$323,'Hours Log'!$A$2:$A$323,"="&'Time Breakdown'!$A13,'Hours Log'!$C$2:$C$323,"="&'Time Breakdown'!$A$1) -> 0 | D13: =SUMIFS('Hours Log'!AF$2:AF$323,'Hours Log'!$A$2:$A$323,"="&'Time Breakdown'!$A13,'Hours Log'!$C$2:$C$323,"="&'Time Breakdown'!$A$1) -> 0 | E13: =SUMIFS('Hours Log'!AG$2:AG$323,'Hours Log'!$A$2:$A$323,"="&'Time Breakdown'!$A13,'Hours Log'!$C$2:$C$323,"="&'Time Breakdown'!$A$1) -> 0 | F13: =SUMIFS('Hours Log'!AH$2:AH$323,'Hours Log'!$A$2:$A$323,"="&'Time Breakdown'!$A13,'Hours Log'!$C$2:$C$323,"="&'Time Breakdown'!$A$1) -> 0 | G13: =SUMIFS('Hours Log'!AI$2:AI$323,'Hours Log'!$A$2:$A$323,"="&'Time Breakdown'!$A13,'Hours Log'!$C$2:$C$323,"="&'Time Breakdown'!$A$1) -> 0 | H13: =SUMIFS('Hours Log'!AJ$2:AJ$323,'Hours Log'!$A$2:$A$323,"="&'Time Breakdown'!$A13,'Hours Log'!$C$2:$C$323,"="&'Time Breakdown'!$A$1) -> 0 | I13: =SUMIFS('Hours Log'!AK$2:AK$323,'Hours Log'!$A$2:$A$323,"="&'Time Breakdown'!$A13,'Hours Log'!$C$2:$C$323,"="&'Time Breakdown'!$A$1) -> 1739.25 | ... U13: =SUMIFS('Hours Log'!AW$2:AW$323,'Hours Log'!$A$2:$A$323,"="&'Time Breakdown'!$A13,'Hours Log'!$C$2:$C$323,"="&'Time Breakdown'!$A$1) -> 340.75 | V13: =SUM(B13:U13) -> 2080
... A46: Wheeler | B46: =SUMIFS('Hours Log'!AD$2:AD$323,'Hours Log'!$A$2:$A$323,"="&'Time Breakdown'!$A46,'Hours Log'!$C$2:$C$323,"="&'Time Breakdown'!$A$1) -> 0 | C46: =SUMIFS('Hours Log'!AE$2:AE$323,'Hours Log'!$A$2:$A$323,"="&'Time Breakdown'!$A46,'Hours Log'!$C$2:$C$323,"="&'Time Breakdown'!$A$1) -> 0 | D46: =SUMIFS('Hours Log'!AF$2:AF$323,'Hours Log'!$A$2:$A$323,"="&'Time Breakdown'!$A46,'Hours Log'!$C$2:$C$323,"="&'Time Breakdown'!$A$1) -> 0 | E46: =SUMIFS('Hours Log'!AG$2:AG$323,'Hours Log'!$A$2:$A$323,"="&'Time Breakdown'!$A46,'Hours Log'!$C$2:$C$323,"="&'Time Breakdown'!$A$1) -> 0 | F46: =SUMIFS('Hours Log'!AH$2:AH$323,'Hours Log'!$A$2:$A$323,"="&'Time Breakdown'!$A46,'Hours Log'!$C$2:$C$323,"="&'Time Breakdown'!$A$1) -> 0 | G46: =SUMIFS('Hours Log'!AI$2:AI$323,'Hours Log'!$A$2:$A$323,"="&'Time Breakdown'!$A46,'Hours Log'!$C$2:$C$323,"="&'Time Breakdown'!$A$1) -> 0 | H46: =SUMIFS('Hours Log'!AJ$2:AJ$323,'Hours Log'!$A$2:$A$323,"="&'Time Breakdown'!$A46,'Hours Log'!$C$2:$C$323,"="&'Time Breakdown'!$A$1) -> 0 | I46: =SUMIFS('Hours Log'!AK$2:AK$323,'Hours Log'!$A$2:$A$323,"="&'Time Breakdown'!$A46,'Hours Log'!$C$2:$C$323,"="&'Time Breakdown'!$A$1) -> 0 | ... U46: =SUMIFS('Hours Log'!AW$2:AW$323,'Hours Log'!$A$2:$A$323,"="&'Time Breakdown'!$A46,'Hours Log'!$C$2:$C$323,"="&'Time Breakdown'!$A$1) -> 0 | V46: =SUM(B46:U46) -> 100
A48: 2025 | B48: Adj-AAMEN | C48: Adj-AM Other | D48: Adj-Apex | E48: Adj-CDBG | F48: Adj-Dig Eng M7 | G48: Adj-DLA | H48: Adj-Drive AM | I48: Adj-ESP | J48: Adj-Fundraising | K48: Adj-Hub | L48: Adj-Hybrid | M48: Adj-IIOT | N48: Adj-LTM | O48: Adj-MBAC | P48: Adj-NavAir | Q48: Adj-Rising Tides | R48: Adj-VGV | S48: Adj-Xjet | T48: Adj-Youth | U48: Adj-YBI | V48: Total
A49: Anderson | B49: =B2/$V2 -> 0 | C49: =C2/$V2 -> 0 | D49: =D2/$V2 -> 0 | E49: =E2/$V2 -> 0 | F49: =F2/$V2 -> 0 | G49: =G2/$V2 -> 0 | H49: =H2/$V2 -> 0 | I49: =I2/$V2 -> 0 | ... U49: =U2/$V2 -> 0 | V49: =SUM(B49:U49) -> 1
A50: Baxter | B50: =B3/$V3 -> 0 | C50: =C3/$V3 -> 0 | D50: =D3/$V3 -> 0 | E50: =E3/$V3 -> 0 | F50: =F3/$V3 -> 0 | G50: =G3/$V3 -> 0 | H50: =H3/$V3 -> 0 | I50: =I3/$V3 -> 1 | ... U50: =U3/$V3 -> 0 | V50: =SUM(B50:U50) -> 1
A51: Bixel | B51: =B4/$V4 -> 0 | C51: =C4/$V4 -> 0 | D51: =D4/$V4 -> 0 | E51: =E4/$V4 -> 0 | F51: =F4/$V4 -> 0 | G51: =G4/$V4 -> 0 | H51: =H4/$V4 -> 0 | I51: =I4/$V4 -> 1 | ... U51: =U4/$V4 -> 0 | V51: =SUM(B51:U51) -> 1
A52: Byers | B52: =B5/$V5 -> 0 | C52: =C5/$V5 -> 0 | D52: =D5/$V5 -> 0 | E52: =E5/$V5 -> 0 | F52: =F5/$V5 -> 0 | G52: =G5/$V5 -> 0 | H52: =H5/$V5 -> 0 | I52: =I5/$V5 -> 0 | ... U52: =U5/$V5 -> 0 | V52: =SUM(B52:U52) -> 1
A53: Canton | B53: =B6/$V6 -> 0 | C53: =C6/$V6 -> 0 | D53: =D6/$V6 -> 0 | E53: =E6/$V6 -> 0 | F53: =F6/$V6 -> 0 | G53: =G6/$V6 -> 0 | H53: =H6/$V6 -> 0 | I53: =I6/$V6 -> 1 | ... U53: =U6/$V6 -> 0 | V53: =SUM(B53:U53) -> 1
A54: Chunn | B54: =B7/$V7 -> 0 | C54: =C7/$V7 -> 0 | D54: =D7/$V7 -> 0 | E54: =E7/$V7 -> 0 | F54: =F7/$V7 -> 0 | G54: =G7/$V7 -> 0 | H54: =H7/$V7 -> 0 | I54: =I7/$V7 -> 1 | ... U54: =U7/$V7 -> 0 | V54: =SUM(B54:U54) -> 1
A55: Davis | B55: =B8/$V8 -> 0 | C55: =C8/$V8 -> 0 | D55: =D8/$V8 -> 0 | E55: =E8/$V8 -> 0 | F55: =F8/$V8 -> 0 | G55: =G8/$V8 -> 0 | H55: =H8/$V8 -> 0 | I55: =I8/$V8 -> 0 | ... U55: =U8/$V8 -> 0 | V55: =SUM(B55:U55) -> 1
A56: Dively | B56: =B9/$V9 -> 0 | C56: =C9/$V9 -> 0 | D56: =D9/$V9 -> 0 | E56: =E9/$V9 -> 0 | F56: =F9/$V9 -> 0 | G56: =G9/$V9 -> 0 | H56: =H9/$V9 -> 0 | I56: =I9/$V9 -> 1 | ... U56: =U9/$V9 -> 0 | V56: =SUM(B56:U56) -> 1
A57: Dwyer | B57: =B10/$V10 -> 0 | C57: =C10/$V10 -> 0 | D57: =D10/$V10 -> 0 | E57: =E10/$V10 -> 0 | F57: =F10/$V10 -> 0 | G57: =G10/$V10 -> 0 | H57: =H10/$V10 -> 0 | I57: =I10/$V10 -> 1 | ... U57: =U10/$V10 -> 0 | V57: =SUM(B57:U57) -> 1
A58: Engel | B58: =B11/$V11 -> 0 | C58: =C11/$V11 -> 0 | D58: =D11/$V11 -> 0 | E58: =E11/$V11 -> 0 | F58: =F11/$V11 -> 0 | G58: =G11/$V11 -> 0 | H58: =H11/$V11 -> 0.55570906 | I58: =I11/$V11 -> 0 | ... U58: =U11/$V11 -> 0 | V58: =SUM(B58:U58) -> 1
A59: Ewing | B59: =B12/$V12 -> 0 | C59: =C12/$V12 -> 0 | D59: =D12/$V12 -> 0 | E59: =E12/$V12 -> 0 | F59: =F12/$V12 -> 0 | G59: =G12/$V12 -> 0 | H59: =H12/$V12 -> 0 | I59: =I12/$V12 -> 0.45574579 | ... U59: =U12/$V12 -> 0.13549648 | V59: =SUM(B59:U59) -> 1
A60: Fiffick | B60: =B13/$V13 -> 0 | C60: =C13/$V13 -> 0 | D60: =D13/$V13 -> 0 | E60: =E13/$V13 -> 0 | F60: =F13/$V13 -> 0 | G60: =G13/$V13 -> 0 | H60: =H13/$V13 -> 0 | I60: =I13/$V13 -> 0.83617788 | ... U60: =U13/$V13 -> 0.16382212 | V60: =SUM(B60:U60) -> 1
... A93: Wheeler | B93: =B46/$V46 -> 0 | C93: =C46/$V46 -> 0 | D93: =D46/$V46 -> 0 | E93: =E46/$V46 -> 0 | F93: =F46/$V46 -> 0 | G93: =G46/$V46 -> 0 | H93: =H46/$V46 -> 0 | I93: =I46/$V46 -> 0 | ... U93: =U46/$V46 -> 0 | V93: =SUM(B93:U93) -> 1
A95: 5139 Wages
C96: FFP Federal | D96: Program | E96: Federal | F96: Federal | G96: Federal | H96: Federal | I96: Federal | J96: Program | K96: Fundraising | L96: Non-Federal | M96: Federal | N96: Federal | O96: Federal | P96: Program | Q96: Program | R96: Federal | S96: Program | T96: Manufacturing Svcs | U96: Program | V96: M&A
A97: 2025 | B97: 2025 Wages | C97: Adj-AAMEN | D97: Adj-AM Other | E97: Adj-Apex | F97: Adj-CDBG | G97: Adj-Dig Eng M7 | H97: Adj-DLA | I97: Adj-Drive AM | J97: Adj-ESP | K97: Adj-Fundraising | L97: Adj-Hub | M97: Adj-Hybrid | N97: Adj-IIOT | O97: Adj-LTM | P97: Adj-MBAC | Q97: Adj-NavAir | R97: Adj-Rising Tides | S97: Adj-VGV | T97: Adj-Xjet | U97: Adj-Youth | V97: Adj-YBI | W97: Total
A98: Alkraein | B98: -53.2 | J98: -53.2 | W98: =SUM(C98:V98) -> -53.2
A99: Anderson | B99: =INDEX('Reference Sheet'!$G$9:$J$100,MATCH('Time Breakdown'!$A99,'Reference Sheet'!$F$9:$F$100),MATCH($A$97,'Reference Sheet'!$G$8:$J$8)) -> 61232 | C99: =$B99*B49 -> 0 | D99: =$B99*C49 -> 0 | E99: =$B99*D49 -> 0 | F99: =$B99*E49 -> 0 | G99: =$B99*F49 -> 0 | H99: =$B99*G49 -> 0 | I99: =$B99*H49 -> 0 | J99: =$B99*I49 -> 0 | ... V99: =$B99*U49 -> 0 | W99: =SUM(C99:V99) -> 61232
A100: Baxter | B100: =INDEX('Reference Sheet'!$G$9:$J$100,MATCH('Time Breakdown'!$A100,'Reference Sheet'!$F$9:$F$100),MATCH($A$97,'Reference Sheet'!$G$8:$J$8)) -> 10805.36 | C100: =$B100*B50 -> 0 | D100: =$B100*C50 -> 0 | E100: =$B100*D50 -> 0 | F100: =$B100*E50 -> 0 | G100: =$B100*F50 -> 0 | H100: =$B100*G50 -> 0 | I100: =$B100*H50 -> 0 | J100: =$B100*I50 -> 10805.36 | ... V100: =$B100*U50 -> 0 | W100: =SUM(C100:V100) -> 10805.36
A101: Bixel | B101: =INDEX('Reference Sheet'!$G$9:$J$100,MATCH('Time Breakdown'!$A101,'Reference Sheet'!$F$9:$F$100),MATCH($A$97,'Reference Sheet'!$G$8:$J$8)) -> 2412.3 | C101: =$B101*B51 -> 0 | D101: =$B101*C51 -> 0 | E101: =$B101*D51 -> 0 | F101: =$B101*E51 -> 0 | G101: =$B101*F51 -> 0 | H101: =$B101*G51 -> 0 | I101: =$B101*H51 -> 0 | J101: =$B101*I51 -> 2412.3 | ... V101: =$B101*U51 -> 0 | W101: =SUM(C101:V101) -> 2412.3
A102: Byers | B102: =INDEX('Reference Sheet'!$G$9:$J$100,MATCH('Time Breakdown'!$A102,'Reference Sheet'!$F$9:$F$100),MATCH($A$97,'Reference Sheet'!$G$8:$J$8)) -> 20280.45 | C102: =$B102*B52 -> 0 | D102: =$B102*C52 -> 0 | E102: =$B102*D52 -> 0 | F102: =$B102*E52 -> 0 | G102: =$B102*F52 -> 0 | H102: =$B102*G52 -> 0 | I102: =$B102*H52 -> 0 | J102: =$B102*I52 -> 0 | ... V102: =$B102*U52 -> 0 | W102: =SUM(C102:V102) -> 20280.45
A103: Canton | B103: =INDEX('Reference Sheet'!$G$9:$J$100,MATCH('Time Breakdown'!$A103,'Reference Sheet'!$F$9:$F$100),MATCH($A$97,'Reference Sheet'!$G$8:$J$8)) -> 9608.44 | C103: =$B103*B53 -> 0 | D103: =$B103*C53 -> 0 | E103: =$B103*D53 -> 0 | F103: =$B103*E53 -> 0 | G103: =$B103*F53 -> 0 | H103: =$B103*G53 -> 0 | I103: =$B103*H53 -> 0 | J103: =$B103*I53 -> 9608.44 | ... V103: =$B103*U53 -> 0 | W103: =SUM(C103:V103) -> 9608.44
A104: Chunn | B104: =INDEX('Reference Sheet'!$G$9:$J$100,MATCH('Time Breakdown'!$A104,'Reference Sheet'!$F$9:$F$100),MATCH($A$97,'Reference Sheet'!$G$8:$J$8)) -> 1430.65 | C104: =$B104*B54 -> 0 | D104: =$B104*C54 -> 0 | E104: =$B104*D54 -> 0 | F104: =$B104*E54 -> 0 | G104: =$B104*F54 -> 0 | H104: =$B104*G54 -> 0 | I104: =$B104*H54 -> 0 | J104: =$B104*I54 -> 1430.65 | ... V104: =$B104*U54 -> 0 | W104: =SUM(C104:V104) -> 1430.65
A105: Davis | B105: =INDEX('Reference Sheet'!$G$9:$J$100,MATCH('Time Breakdown'!$A105,'Reference Sheet'!$F$9:$F$100),MATCH($A$97,'Reference Sheet'!$G$8:$J$8)) -> 56212.62 | C105: =$B105*B55 -> 0 | D105: =$B105*C55 -> 0 | E105: =$B105*D55 -> 0 | F105: =$B105*E55 -> 0 | G105: =$B105*F55 -> 0 | H105: =$B105*G55 -> 0 | I105: =$B105*H55 -> 0 | J105: =$B105*I55 -> 0 | ... V105: =$B105*U55 -> 0 | W105: =SUM(C105:V105) -> 56212.62
A106: Dively | B106: =INDEX('Reference Sheet'!$G$9:$J$100,MATCH('Time Breakdown'!$A106,'Reference Sheet'!$F$9:$F$100),MATCH($A$97,'Reference Sheet'!$G$8:$J$8)) -> 12715.75 | C106: =$B106*B56 -> 0 | D106: =$B106*C56 -> 0 | E106: =$B106*D56 -> 0 | F106: =$B106*E56 -> 0 | G106: =$B106*F56 -> 0 | H106: =$B106*G56 -> 0 | I106: =$B106*H56 -> 0 | J106: =$B106*I56 -> 12715.75 | ... V106: =$B106*U56 -> 0 | W106: =SUM(C106:V106) -> 12715.75
...

Sheet 09.04.26 Time Total
A1: Year | B1: 2025
A3: Row Labels | B3: Sum of AAMEN | C3: Sum of AM Other | D3: Sum of Apex | E3: Sum of Dig Eng M7 | F3: Sum of DLA | G3: Sum of Drive AM | H3: Sum of ESP | I3: Sum of Fundraising | J3: Sum of Hub | K3: Sum of Hybrid | L3: Sum of IIOT | M3: Sum of LTM | N3: Sum of MBAC | O3: Sum of NavAir (AM-O) | P3: Sum of Rising Tides | Q3: Sum of VGV | R3: Sum of Xjet (AM-O) | S3: Sum of Youth | T3: Sum of YBI
A4: Anderson | N4: 100
A5: Baxter | H5: 100
A6: Bixel | H6: 100
A7: Byers | S7: 100
A8: Canton | H8: 100
A9: Chunn | H9: 100
A10: Davis | N10: 100
A11: Dively | H11: 100
A12: Dwyer | H12: 100
A13: Engel | G13: 1180 | M13: 948
A14: Ewing | H14: 1189.41 | I14: 126.32 | J14: 815 | K14: 57.6 | N14: 52.5 | P14: 2 | Q14: 6 | S14: 19.5 | T14: 353.62
A15: Fiffick | H15: 1739.25 | T15: 340.75
A16: Fries | H16: 100
A17: Gaffney | E17: 259 | G17: 554.5 | H17: 285 | J17: 627 | K17: 434 | M17: 178 | P17: 345
A18: Gordon | H18: 100
A19: Griffin | N19: 100
A20: Hurd | H20: 100
A21: Islam | H21: 100
A22: Jadue | I22: 50 | T22: 50
A23: Jafarli | H23: 100
A24: Jaric | F24: 11 | G24: 756 | K24: 56 | L24: 78 | M24: 131 | P24: 144 | T24: 953
A25: Kale | G25: 223 | H25: 1383 | J25: 1001 | P25: 40
A26: Kelly | C26: 35 | H26: 925 | I26: 31 | N26: 84 | Q26: 7.5 | S26: 49 | T26: 1038.5
A27: Kummari | H27: 100
A28: Lawrence | H28: 100
A29: Leonard | H29: 100
A30: Longo | E30: 316 | K30: 654 | P30: 1115
A31: Metzinger | H31: 37 | K31: 120 | P31: 120 | T31: 504
A32: Micco | H32: 100
A33: Moreno | H33: 100
A34: Negro | G34: 973 | P34: 664 | R34: 469
A35: Pasha | H35: 480 | N35: 12
A36: Payich | S36: 100
A37: Politsky | H37: 810 | I37: 526 | T37: 885
A38: Precurato | H38: 100
A39: Rabenstine | H39: 100
A40: Rhoades | H40: 93.42 | N40: 0.85 | T40: 5.73
A41: Roch | H41: 100
...

Sheet Hours Log
A1: Name | B1: Month | C1: Year | D1: Hourly Rate | E1: Fringe Rate | F1: FB Rate | G1: AAMEN | H1: AM Other | I1: Apex | J1: CDBG | K1: Dig Eng M7 | L1: DLA | M1: Drive AM | N1: ESP | O1: Fundraising | P1: Hub | Q1: Hybrid | R1: IIOT | S1: LTM | T1: MBAC | U1: NavAir (AM-O) | V1: Rising Tides | W1: VGV | X1: Xjet (AM-O) | Y1: Youth | Z1: YBI | AA1: TS Hours | AB1: Allow Hours | AC1: Variance | AD1: Adj-AAMEN | AE1: Adj-AM Other | AF1: Adj-Apex | AG1: Adj-CDBG | AH1: Adj-Dig Eng M7 | AI1: Adj-DLA | AJ1: Adj-Drive AM | AK1: Adj-ESP | AL1: Adj-Fundraising | AM1: Adj-Hub | AN1: Adj-Hybrid | AO1: Adj-IIOT | AP1: Adj-LTM | AQ1: Adj-MBAC | AR1: Adj-NavAir | AS1: Adj-Rising Tides | AT1: Adj-VGV | AU1: Adj-Xjet | AV1: Adj-Youth | AW1: Adj-YBI | AX1: ADJ TS Hours | AY1: X-AAMEN | AZ1: X-AM Other | BA1: X-Apex | BB1: X=CDBG | BC1: X-Dig Eng M7 | BD1: X-DLA | BE1: X-Drive AM | BF1: X-ESP | BG1: X-Fundraising | BH1: X-Hub | BI1: X-Hybrid | BJ1: X-IIOT | BK1: X-LTM | BL1: X-MBAC | BM1: X-NavAir | BN1: X-Rising Tides | BO1: X-VGV | BP1: X-Xjet | BQ1: X-Youth | BR1: X-YBI
A2: Engel | B2: March | C2: 2024 | D2: =INDEX('Reference Sheet'!$G$9:$J$100, MATCH(A2,'Reference Sheet'!$F$9:$F$100,0), MATCH(C2,'Reference Sheet'!$G$8:$J$8,0))/2080 -> 35.239992 | E2: =VLOOKUP(C2,'Reference Sheet'!$A$2:$B$5,2) -> 0.1913 | F2: =D2*(1+E2) -> 41.981402 | M2: 80 | AA2: =SUM(G2:Z2) -> 80 | AB2: 80 | AC2: =AB2-AA2 -> 0 | AD2: =(G2/$AA2)*$AB2 -> 0 | AE2: =(H2/$AA2)*$AB2 -> 0 | AF2: =(I2/$AA2)*$AB2 -> 0 | AG2: =(J2/$AA2)*$AB2 -> 0 | AH2: =(K2/$AA2)*$AB2 -> 0 | AI2: =(L2/$AA2)*$AB2 -> 0 | AJ2: =(M2/$AA2)*$AB2 -> 80 | AK2: =(N2/$AA2)*$AB2 -> 0 | ... AW2: =(Z2/$AA2)*$AB2 -> 0 | AX2: =SUM(AF2:AW2) -> 80 | AY2: =$F2*AD2 -> 0 | AZ2: =$F2*AE2 -> 0 | BA2: =$F2*AF2 -> 0 | BB2: =$F2*AG2 -> 0 | BC2: =$F2*AH2 -> 0 | BD2: =$F2*AI2 -> 0 | BE2: =$F2*AJ2 -> 3358.5122 | BF2: =$F2*AK2 -> 0 | ... BR2: =$F2*AW2 -> 0
A3: Engel | B3: June | C3: 2024 | D3: =INDEX('Reference Sheet'!$G$9:$J$100, MATCH(A3,'Reference Sheet'!$F$9:$F$100,0), MATCH(C3,'Reference Sheet'!$G$8:$J$8,0))/2080 -> 35.239992 | E3: =VLOOKUP(C3,'Reference Sheet'!$A$2:$B$5,2) -> 0.1913 | F3: =D3*(1+E3) -> 41.981402 | M3: 168 | AA3: =SUM(G3:Z3) -> 168 | AB3: =IF(OR(B3="",C3=""),"",SUMIFS('Reference Sheet'!$D$9:$D$42,'Reference Sheet'!$A$9:$A$42,C3,'Reference Sheet'!$B$9:$B$42,B3)) -> 160 | AC3: =AB3-AA3 -> -8 | AD3: =(G3/$AA3)*$AB3 -> 0 | AE3: =(H3/$AA3)*$AB3 -> 0 | AF3: =(I3/$AA3)*$AB3 -> 0 | AG3: =(J3/$AA3)*$AB3 -> 0 | AH3: =(K3/$AA3)*$AB3 -> 0 | AI3: =(L3/$AA3)*$AB3 -> 0 | AJ3: =(M3/$AA3)*$AB3 -> 160 | AK3: =(N3/$AA3)*$AB3 -> 0 | ... AW3: =(Z3/$AA3)*$AB3 -> 0 | AX3: =SUM(AF3:AW3) -> 160 | AY3: =$F3*AD3 -> 0 | AZ3: =$F3*AE3 -> 0 | BA3: =$F3*AF3 -> 0 | BB3: =$F3*AG3 -> 0 | BC3: =$F3*AH3 -> 0 | BD3: =$F3*AI3 -> 0 | BE3: =$F3*AJ3 -> 6717.0244 | BF3: =$F3*AK3 -> 0 | ... BR3: =$F3*AW3 -> 0
A4: Engel | B4: September | C4: 2024 | D4: =INDEX('Reference Sheet'!$G$9:$J$100, MATCH(A4,'Reference Sheet'!$F$9:$F$100,0), MATCH(C4,'Reference Sheet'!$G$8:$J$8,0))/2080 -> 35.239992 | E4: =VLOOKUP(C4,'Reference Sheet'!$A$2:$B$5,2) -> 0.1913 | F4: =D4*(1+E4) -> 41.981402 | M4: 168 | AA4: =SUM(G4:Z4) -> 168 | AB4: =IF(OR(B4="",C4=""),"",SUMIFS('Reference Sheet'!$D$9:$D$42,'Reference Sheet'!$A$9:$A$42,C4,'Reference Sheet'!$B$9:$B$42,B4)) -> 168 | AC4: =AB4-AA4 -> 0 | AD4: =(G4/$AA4)*$AB4 -> 0 | AE4: =(H4/$AA4)*$AB4 -> 0 | AF4: =(I4/$AA4)*$AB4 -> 0 | AG4: =(J4/$AA4)*$AB4 -> 0 | AH4: =(K4/$AA4)*$AB4 -> 0 | AI4: =(L4/$AA4)*$AB4 -> 0 | AJ4: =(M4/$AA4)*$AB4 -> 168 | AK4: =(N4/$AA4)*$AB4 -> 0 | ... AW4: =(Z4/$AA4)*$AB4 -> 0 | AX4: =SUM(AF4:AW4) -> 168 | AY4: =$F4*AD4 -> 0 | AZ4: =$F4*AE4 -> 0 | BA4: =$F4*AF4 -> 0 | BB4: =$F4*AG4 -> 0 | BC4: =$F4*AH4 -> 0 | BD4: =$F4*AI4 -> 0 | BE4: =$F4*AJ4 -> 7052.8756 | BF4: =$F4*AK4 -> 0 | ... BR4: =$F4*AW4 -> 0
A5: Engel | B5: April | C5: 2024 | D5: =INDEX('Reference Sheet'!$G$9:$J$100, MATCH(A5,'Reference Sheet'!$F$9:$F$100,0), MATCH(C5,'Reference Sheet'!$G$8:$J$8,0))/2080 -> 35.239992 | E5: =VLOOKUP(C5,'Reference Sheet'!$A$2:$B$5,2) -> 0.1913 | F5: =D5*(1+E5) -> 41.981402 | M5: 176 | AA5: =SUM(G5:Z5) -> 176 | AB5: =IF(OR(B5="",C5=""),"",SUMIFS('Reference Sheet'!$D$9:$D$42,'Reference Sheet'!$A$9:$A$42,C5,'Reference Sheet'!$B$9:$B$42,B5)) -> 176 | AC5: =AB5-AA5 -> 0 | AD5: =(G5/$AA5)*$AB5 -> 0 | AE5: =(H5/$AA5)*$AB5 -> 0 | AF5: =(I5/$AA5)*$AB5 -> 0 | AG5: =(J5/$AA5)*$AB5 -> 0 | AH5: =(K5/$AA5)*$AB5 -> 0 | AI5: =(L5/$AA5)*$AB5 -> 0 | AJ5: =(M5/$AA5)*$AB5 -> 176 | AK5: =(N5/$AA5)*$AB5 -> 0 | ... AW5: =(Z5/$AA5)*$AB5 -> 0 | AX5: =SUM(AF5:AW5) -> 176 | AY5: =$F5*AD5 -> 0 | AZ5: =$F5*AE5 -> 0 | BA5: =$F5*AF5 -> 0 | BB5: =$F5*AG5 -> 0 | BC5: =$F5*AH5 -> 0 | BD5: =$F5*AI5 -> 0 | BE5: =$F5*AJ5 -> 7388.7268 | BF5: =$F5*AK5 -> 0 | ... BR5: =$F5*AW5 -> 0
A6: Engel | B6: August | C6: 2024 | D6: =INDEX('Reference Sheet'!$G$9:$J$100, MATCH(A6,'Reference Sheet'!$F$9:$F$100,0), MATCH(C6,'Reference Sheet'!$G$8:$J$8,0))/2080 -> 35.239992 | E6: =VLOOKUP(C6,'Reference Sheet'!$A$2:$B$5,2) -> 0.1913 | F6: =D6*(1+E6) -> 41.981402 | M6: 176 | AA6: =SUM(G6:Z6) -> 176 | AB6: =IF(OR(B6="",C6=""),"",SUMIFS('Reference Sheet'!$D$9:$D$42,'Reference Sheet'!$A$9:$A$42,C6,'Reference Sheet'!$B$9:$B$42,B6)) -> 176 | AC6: =AB6-AA6 -> 0 | AD6: =(G6/$AA6)*$AB6 -> 0 | AE6: =(H6/$AA6)*$AB6 -> 0 | AF6: =(I6/$AA6)*$AB6 -> 0 | AG6: =(J6/$AA6)*$AB6 -> 0 | AH6: =(K6/$AA6)*$AB6 -> 0 | AI6: =(L6/$AA6)*$AB6 -> 0 | AJ6: =(M6/$AA6)*$AB6 -> 176 | AK6: =(N6/$AA6)*$AB6 -> 0 | ... AW6: =(Z6/$AA6)*$AB6 -> 0 | AX6: =SUM(AF6:AW6) -> 176 | AY6: =$F6*AD6 -> 0 | AZ6: =$F6*AE6 -> 0 | BA6: =$F6*AF6 -> 0 | BB6: =$F6*AG6 -> 0 | BC6: =$F6*AH6 -> 0 | BD6: =$F6*AI6 -> 0 | BE6: =$F6*AJ6 -> 7388.7268 | BF6: =$F6*AK6 -> 0 | ... BR6: =$F6*AW6 -> 0
A7: Engel | B7: November | C7: 2024 | D7: =INDEX('Reference Sheet'!$G$9:$J$100, MATCH(A7,'Reference Sheet'!$F$9:$F$100,0), MATCH(C7,'Reference Sheet'!$G$8:$J$8,0))/2080 -> 35.239992 | E7: =VLOOKUP(C7,'Reference Sheet'!$A$2:$B$5,2) -> 0.1913 | F7: =D7*(1+E7) -> 41.981402 | M7: 100 | S7: 80 | AA7: =SUM(G7:Z7) -> 180 | AB7: =IF(OR(B7="",C7=""),"",SUMIFS('Reference Sheet'!$D$9:$D$42,'Reference Sheet'!$A$9:$A$42,C7,'Reference Sheet'!$B$9:$B$42,B7)) -> 168 | AC7: =AB7-AA7 -> -12 | AD7: =(G7/$AA7)*$AB7 -> 0 | AE7: =(H7/$AA7)*$AB7 -> 0 | AF7: =(I7/$AA7)*$AB7 -> 0 | AG7: =(J7/$AA7)*$AB7 -> 0 | AH7: =(K7/$AA7)*$AB7 -> 0 | AI7: =(L7/$AA7)*$AB7 -> 0 | AJ7: =(M7/$AA7)*$AB7 -> 93.333333 | AK7: =(N7/$AA7)*$AB7 -> 0 | ... AW7: =(Z7/$AA7)*$AB7 -> 0 | AX7: =SUM(AF7:AW7) -> 168 | AY7: =$F7*AD7 -> 0 | AZ7: =$F7*AE7 -> 0 | BA7: =$F7*AF7 -> 0 | BB7: =$F7*AG7 -> 0 | BC7: =$F7*AH7 -> 0 | BD7: =$F7*AI7 -> 0 | BE7: =$F7*AJ7 -> 3918.2642 | BF7: =$F7*AK7 -> 0 | ... BR7: =$F7*AW7 -> 0
A8: Engel | B8: December | C8: 2024 | D8: =INDEX('Reference Sheet'!$G$9:$J$100, MATCH(A8,'Reference Sheet'!$F$9:$F$100,0), MATCH(C8,'Reference Sheet'!$G$8:$J$8,0))/2080 -> 35.239992 | E8: =VLOOKUP(C8,'Reference Sheet'!$A$2:$B$5,2) -> 0.1913 | F8: =D8*(1+E8) -> 41.981402 | M8: 100 | S8: 80 | AA8: =SUM(G8:Z8) -> 180 | AB8: =IF(OR(B8="",C8=""),"",SUMIFS('Reference Sheet'!$D$9:$D$42,'Reference Sheet'!$A$9:$A$42,C8,'Reference Sheet'!$B$9:$B$42,B8)) -> 176 | AC8: =AB8-AA8 -> -4 | AD8: =(G8/$AA8)*$AB8 -> 0 | AE8: =(H8/$AA8)*$AB8 -> 0 | AF8: =(I8/$AA8)*$AB8 -> 0 | AG8: =(J8/$AA8)*$AB8 -> 0 | AH8: =(K8/$AA8)*$AB8 -> 0 | AI8: =(L8/$AA8)*$AB8 -> 0 | AJ8: =(M8/$AA8)*$AB8 -> 97.777778 | AK8: =(N8/$AA8)*$AB8 -> 0 | ... AW8: =(Z8/$AA8)*$AB8 -> 0 | AX8: =SUM(AF8:AW8) -> 176 | AY8: =$F8*AD8 -> 0 | AZ8: =$F8*AE8 -> 0 | BA8: =$F8*AF8 -> 0 | BB8: =$F8*AG8 -> 0 | BC8: =$F8*AH8 -> 0 | BD8: =$F8*AI8 -> 0 | BE8: =$F8*AJ8 -> 4104.8482 | BF8: =$F8*AK8 -> 0 | ... BR8: =$F8*AW8 -> 0
A9: Engel | B9: October | C9: 2024 | D9: =INDEX('Reference Sheet'!$G$9:$J$100, MATCH(A9,'Reference Sheet'!$F$9:$F$100,0), MATCH(C9,'Reference Sheet'!$G$8:$J$8,0))/2080 -> 35.239992 | E9: =VLOOKUP(C9,'Reference Sheet'!$A$2:$B$5,2) -> 0.1913 | F9: =D9*(1+E9) -> 41.981402 | M9: 100 | S9: 83 | AA9: =SUM(G9:Z9) -> 183 | AB9: =IF(OR(B9="",C9=""),"",SUMIFS('Reference Sheet'!$D$9:$D$42,'Reference Sheet'!$A$9:$A$42,C9,'Reference Sheet'!$B$9:$B$42,B9)) -> 184 | AC9: =AB9-AA9 -> 1 | AD9: =(G9/$AA9)*$AB9 -> 0 | AE9: =(H9/$AA9)*$AB9 -> 0 | AF9: =(I9/$AA9)*$AB9 -> 0 | AG9: =(J9/$AA9)*$AB9 -> 0 | AH9: =(K9/$AA9)*$AB9 -> 0 | AI9: =(L9/$AA9)*$AB9 -> 0 | AJ9: =(M9/$AA9)*$AB9 -> 100.54645 | AK9: =(N9/$AA9)*$AB9 -> 0 | ... AW9: =(Z9/$AA9)*$AB9 -> 0 | AX9: =SUM(AF9:AW9) -> 184 | AY9: =$F9*AD9 -> 0 | AZ9: =$F9*AE9 -> 0 | BA9: =$F9*AF9 -> 0 | BB9: =$F9*AG9 -> 0 | BC9: =$F9*AH9 -> 0 | BD9: =$F9*AI9 -> 0 | BE9: =$F9*AJ9 -> 4221.0809 | BF9: =$F9*AK9 -> 0 | ... BR9: =$F9*AW9 -> 0
A10: Engel | B10: May | C10: 2024 | D10: =INDEX('Reference Sheet'!$G$9:$J$100, MATCH(A10,'Reference Sheet'!$F$9:$F$100,0), MATCH(C10,'Reference Sheet'!$G$8:$J$8,0))/2080 -> 35.239992 | E10: =VLOOKUP(C10,'Reference Sheet'!$A$2:$B$5,2) -> 0.1913 | F10: =D10*(1+E10) -> 41.981402 | M10: 184 | AA10: =SUM(G10:Z10) -> 184 | AB10: =IF(OR(B10="",C10=""),"",SUMIFS('Reference Sheet'!$D$9:$D$42,'Reference Sheet'!$A$9:$A$42,C10,'Reference Sheet'!$B$9:$B$42,B10)) -> 184 | AC10: =AB10-AA10 -> 0 | AD10: =(G10/$AA10)*$AB10 -> 0 | AE10: =(H10/$AA10)*$AB10 -> 0 | AF10: =(I10/$AA10)*$AB10 -> 0 | AG10: =(J10/$AA10)*$AB10 -> 0 | AH10: =(K10/$AA10)*$AB10 -> 0 | AI10: =(L10/$AA10)*$AB10 -> 0 | AJ10: =(M10/$AA10)*$AB10 -> 184 | AK10: =(N10/$AA10)*$AB10 -> 0 | ... AW10: =(Z10/$AA10)*$AB10 -> 0 | AX10: =SUM(AF10:AW10) -> 184 | AY10: =$F10*AD10 -> 0 | AZ10: =$F10*AE10 -> 0 | BA10: =$F10*AF10 -> 0 | BB10: =$F10*AG10 -> 0 | BC10: =$F10*AH10 -> 0 | BD10: =$F10*AI10 -> 0 | BE10: =$F10*AJ10 -> 7724.578 | BF10: =$F10*AK10 -> 0 | ... BR10: =$F10*AW10 -> 0
A11: Engel | B11: July | C11: 2024 | D11: =INDEX('Reference Sheet'!$G$9:$J$100, MATCH(A11,'Reference Sheet'!$F$9:$F$100,0), MATCH(C11,'Reference Sheet'!$G$8:$J$8,0))/2080 -> 35.239992 | E11: =VLOOKUP(C11,'Reference Sheet'!$A$2:$B$5,2) -> 0.1913 | F11: =D11*(1+E11) -> 41.981402 | M11: 184 | AA11: =SUM(G11:Z11) -> 184 | AB11: =IF(OR(B11="",C11=""),"",SUMIFS('Reference Sheet'!$D$9:$D$42,'Reference Sheet'!$A$9:$A$42,C11,'Reference Sheet'!$B$9:$B$42,B11)) -> 184 | AC11: =AB11-AA11 -> 0 | AD11: =(G11/$AA11)*$AB11 -> 0 | AE11: =(H11/$AA11)*$AB11 -> 0 | AF11: =(I11/$AA11)*$AB11 -> 0 | AG11: =(J11/$AA11)*$AB11 -> 0 | AH11: =(K11/$AA11)*$AB11 -> 0 | AI11: =(L11/$AA11)*$AB11 -> 0 | AJ11: =(M11/$AA11)*$AB11 -> 184 | AK11: =(N11/$AA11)*$AB11 -> 0 | ... AW11: =(Z11/$AA11)*$AB11 -> 0 | AX11: =SUM(AF11:AW11) -> 184 | AY11: =$F11*AD11 -> 0 | AZ11: =$F11*AE11 -> 0 | BA11: =$F11*AF11 -> 0 | BB11: =$F11*AG11 -> 0 | BC11: =$F11*AH11 -> 0 | BD11: =$F11*AI11 -> 0 | BE11: =$F11*AJ11 -> 7724.578 | BF11: =$F11*AK11 -> 0 | ... BR11: =$F11*AW11 -> 0
A12: Engel | B12: May | C12: 2025 | D12: =INDEX('Reference Sheet'!$G$9:$J$100, MATCH(A12,'Reference Sheet'!$F$9:$F$100,0), MATCH(C12,'Reference Sheet'!$G$8:$J$8,0))/2080 -> 37.647947 | E12: =VLOOKUP(C12,'Reference Sheet'!$A$2:$B$5,2) -> 0.2245 | F12: =D12*(1+E12) -> 46.099911 | M12: 100 | S12: 56 | AA12: =SUM(G12:Z12) -> 156 | AB12: =IF(OR(B12="",C12=""),"",SUMIFS('Reference Sheet'!$D$9:$D$42,'Reference Sheet'!$A$9:$A$42,C12,'Reference Sheet'!$B$9:$B$42,B12)) -> 176 | AC12: =AB12-AA12 -> 20 | AD12: =(G12/$AA12)*$AB12 -> 0 | AE12: =(H12/$AA12)*$AB12 -> 0 | AF12: =(I12/$AA12)*$AB12 -> 0 | AG12: =(J12/$AA12)*$AB12 -> 0 | AH12: =(K12/$AA12)*$AB12 -> 0 | AI12: =(L12/$AA12)*$AB12 -> 0 | AJ12: =(M12/$AA12)*$AB12 -> 112.82051 | AK12: =(N12/$AA12)*$AB12 -> 0 | ... AW12: =(Z12/$AA12)*$AB12 -> 0 | AX12: =SUM(AF12:AW12) -> 176 | AY12: =$F12*AD12 -> 0 | AZ12: =$F12*AE12 -> 0 | BA12: =$F12*AF12 -> 0 | BB12: =$F12*AG12 -> 0 | BC12: =$F12*AH12 -> 0 | BD12: =$F12*AI12 -> 0 | BE12: =$F12*AJ12 -> 5201.0156 | BF12: =$F12*AK12 -> 0 | ... BR12: =$F12*AW12 -> 0
A13: Engel | B13: February | C13: 2025 | D13: =INDEX('Reference Sheet'!$G$9:$J$100, MATCH(A13,'Reference Sheet'!$F$9:$F$100,0), MATCH(C13,'Reference Sheet'!$G$8:$J$8,0))/2080 -> 37.647947 | E13: =VLOOKUP(C13,'Reference Sheet'!$A$2:$B$5,2) -> 0.2245 | F13: =D13*(1+E13) -> 46.099911 | M13: 80 | S13: 80 | AA13: =SUM(G13:Z13) -> 160 | AB13: =IF(OR(B13="",C13=""),"",SUMIFS('Reference Sheet'!$D$9:$D$42,'Reference Sheet'!$A$9:$A$42,C13,'Reference Sheet'!$B$9:$B$42,B13)) -> 160 | AC13: =AB13-AA13 -> 0 | AD13: =(G13/$AA13)*$AB13 -> 0 | AE13: =(H13/$AA13)*$AB13 -> 0 | AF13: =(I13/$AA13)*$AB13 -> 0 | AG13: =(J13/$AA13)*$AB13 -> 0 | AH13: =(K13/$AA13)*$AB13 -> 0 | AI13: =(L13/$AA13)*$AB13 -> 0 | AJ13: =(M13/$AA13)*$AB13 -> 80 | AK13: =(N13/$AA13)*$AB13 -> 0 | ... AW13: =(Z13/$AA13)*$AB13 -> 0 | AX13: =SUM(AF13:AW13) -> 160 | AY13: =$F13*AD13 -> 0 | AZ13: =$F13*AE13 -> 0 | BA13: =$F13*AF13 -> 0 | BB13: =$F13*AG13 -> 0 | BC13: =$F13*AH13 -> 0 | BD13: =$F13*AI13 -> 0 | BE13: =$F13*AJ13 -> 3687.9929 | BF13: =$F13*AK13 -> 0 | ... BR13: =$F13*AW13 -> 0
A14: Engel | B14: January | C14: 2025 | D14: =INDEX('Reference Sheet'!$G$9:$J$100, MATCH(A14,'Reference Sheet'!$F$9:$F$100,0), MATCH(C14,'Reference Sheet'!$G$8:$J$8,0))/2080 -> 37.647947 | E14: =VLOOKUP(C14,'Reference Sheet'!$A$2:$B$5,2) -> 0.2245 | F14: =D14*(1+E14) -> 46.099911 | M14: 100 | S14: 80 | AA14: =SUM(G14:Z14) -> 180 | AB14: =IF(OR(B14="",C14=""),"",SUMIFS('Reference Sheet'!$D$9:$D$42,'Reference Sheet'!$A$9:$A$42,C14,'Reference Sheet'!$B$9:$B$42,B14)) -> 184 | AC14: =AB14-AA14 -> 4 | AD14: =(G14/$AA14)*$AB14 -> 0 | AE14: =(H14/$AA14)*$AB14 -> 0 | AF14: =(I14/$AA14)*$AB14 -> 0 | AG14: =(J14/$AA14)*$AB14 -> 0 | AH14: =(K14/$AA14)*$AB14 -> 0 | AI14: =(L14/$AA14)*$AB14 -> 0 | AJ14: =(M14/$AA14)*$AB14 -> 102.22222 | AK14: =(N14/$AA14)*$AB14 -> 0 | ... AW14: =(Z14/$AA14)*$AB14 -> 0 | AX14: =SUM(AF14:AW14) -> 184 | AY14: =$F14*AD14 -> 0 | AZ14: =$F14*AE14 -> 0 | BA14: =$F14*AF14 -> 0 | BB14: =$F14*AG14 -> 0 | BC14: =$F14*AH14 -> 0 | BD14: =$F14*AI14 -> 0 | BE14: =$F14*AJ14 -> 4712.4354 | BF14: =$F14*AK14 -> 0 | ... BR14: =$F14*AW14 -> 0
A15: Engel | B15: March | C15: 2025 | D15: =INDEX('Reference Sheet'!$G$9:$J$100, MATCH(A15,'Reference Sheet'!$F$9:$F$100,0), MATCH(C15,'Reference Sheet'!$G$8:$J$8,0))/2080 -> 37.647947 | E15: =VLOOKUP(C15,'Reference Sheet'!$A$2:$B$5,2) -> 0.2245 | F15: =D15*(1+E15) -> 46.099911 | M15: 100 | S15: 80 | AA15: =SUM(G15:Z15) -> 180 | AB15: =IF(OR(B15="",C15=""),"",SUMIFS('Reference Sheet'!$D$9:$D$42,'Reference Sheet'!$A$9:$A$42,C15,'Reference Sheet'!$B$9:$B$42,B15)) -> 168 | AC15: =AB15-AA15 -> -12 | AD15: =(G15/$AA15)*$AB15 -> 0 | AE15: =(H15/$AA15)*$AB15 -> 0 | AF15: =(I15/$AA15)*$AB15 -> 0 | AG15: =(J15/$AA15)*$AB15 -> 0 | AH15: =(K15/$AA15)*$AB15 -> 0 | AI15: =(L15/$AA15)*$AB15 -> 0 | AJ15: =(M15/$AA15)*$AB15 -> 93.333333 | AK15: =(N15/$AA15)*$AB15 -> 0 | ... AW15: =(Z15/$AA15)*$AB15 -> 0 | AX15: =SUM(AF15:AW15) -> 168 | AY15: =$F15*AD15 -> 0 | AZ15: =$F15*AE15 -> 0 | BA15: =$F15*AF15 -> 0 | BB15: =$F15*AG15 -> 0 | BC15: =$F15*AH15 -> 0 | BD15: =$F15*AI15 -> 0 | BE15: =$F15*AJ15 -> 4302.6584 | BF15: =$F15*AK15 -> 0 | ... BR15: =$F15*AW15 -> 0
A16: Engel | B16: April | C16: 2025 | D16: =INDEX('Reference Sheet'!$G$9:$J$100, MATCH(A16,'Reference Sheet'!$F$9:$F$100,0), MATCH(C16,'Reference Sheet'!$G$8:$J$8,0))/2080 -> 37.647947 | E16: =VLOOKUP(C16,'Reference Sheet'!$A$2:$B$5,2) -> 0.2245 | F16: =D16*(1+E16) -> 46.099911 | M16: 100 | S16: 80 | AA16: =SUM(G16:Z16) -> 180 | AB16: =IF(OR(B16="",C16=""),"",SUMIFS('Reference Sheet'!$D$9:$D$42,'Reference Sheet'!$A$9:$A$42,C16,'Reference Sheet'!$B$9:$B$42,B16)) -> 176 | AC16: =AB16-AA16 -> -4 | AD16: =(G16/$AA16)*$AB16 -> 0 | AE16: =(H16/$AA16)*$AB16 -> 0 | AF16: =(I16/$AA16)*$AB16 -> 0 | AG16: =(J16/$AA16)*$AB16 -> 0 | AH16: =(K16/$AA16)*$AB16 -> 0 | AI16: =(L16/$AA16)*$AB16 -> 0 | AJ16: =(M16/$AA16)*$AB16 -> 97.777778 | AK16: =(N16/$AA16)*$AB16 -> 0 | ... AW16: =(Z16/$AA16)*$AB16 -> 0 | AX16: =SUM(AF16:AW16) -> 176 | AY16: =$F16*AD16 -> 0 | AZ16: =$F16*AE16 -> 0 | BA16: =$F16*AF16 -> 0 | BB16: =$F16*AG16 -> 0 | BC16: =$F16*AH16 -> 0 | BD16: =$F16*AI16 -> 0 | BE16: =$F16*AJ16 -> 4507.5469 | BF16: =$F16*AK16 -> 0 | ... BR16: =$F16*AW16 -> 0
A17: Engel | B17: July | C17: 2025 | D17: =INDEX('Reference Sheet'!$G$9:$J$100, MATCH(A17,'Reference Sheet'!$F$9:$F$100,0), MATCH(C17,'Reference Sheet'!$G$8:$J$8,0))/2080 -> 37.647947 | E17: =VLOOKUP(C17,'Reference Sheet'!$A$2:$B$5,2) -> 0.2245 | F17: =D17*(1+E17) -> 46.099911 | M17: 100 | S17: 80 | AA17: =SUM(G17:Z17) -> 180 | AB17: =IF(OR(B17="",C17=""),"",SUMIFS('Reference Sheet'!$D$9:$D$42,'Reference Sheet'!$A$9:$A$42,C17,'Reference Sheet'!$B$9:$B$42,B17)) -> 184 | AC17: =AB17-AA17 -> 4 | AD17: =(G17/$AA17)*$AB17 -> 0 | AE17: =(H17/$AA17)*$AB17 -> 0 | AF17: =(I17/$AA17)*$AB17 -> 0 | AG17: =(J17/$AA17)*$AB17 -> 0 | AH17: =(K17/$AA17)*$AB17 -> 0 | AI17: =(L17/$AA17)*$AB17 -> 0 | AJ17: =(M17/$AA17)*$AB17 -> 102.22222 | AK17: =(N17/$AA17)*$AB17 -> 0 | ... AW17: =(Z17/$AA17)*$AB17 -> 0 | AX17: =SUM(AF17:AW17) -> 184 | AY17: =$F17*AD17 -> 0 | AZ17: =$F17*AE17 -> 0 | BA17: =$F17*AF17 -> 0 | BB17: =$F17*AG17 -> 0 | BC17: =$F17*AH17 -> 0 | BD17: =$F17*AI17 -> 0 | BE17: =$F17*AJ17 -> 4712.4354 | BF17: =$F17*AK17 -> 0 | ... BR17: =$F17*AW17 -> 0
A18: Engel | B18: August | C18: 2025 | D18: =INDEX('Reference Sheet'!$G$9:$J$100, MATCH(A18,'Reference Sheet'!$F$9:$F$100,0), MATCH(C18,'Reference Sheet'!$G$8:$J$8,0))/2080 -> 37.647947 | E18: =VLOOKUP(C18,'Reference Sheet'!$A$2:$B$5,2) -> 0.2245 | F18: =D18*(1+E18) -> 46.099911 | M18: 100 | S18: 80 | AA18: =SUM(G18:Z18) -> 180 | AB18: =IF(OR(B18="",C18=""),"",SUMIFS('Reference Sheet'!$D$9:$D$42,'Reference Sheet'!$A$9:$A$42,C18,'Reference Sheet'!$B$9:$B$42,B18)) -> 168 | AC18: =AB18-AA18 -> -12 | AD18: =(G18/$AA18)*$AB18 -> 0 | AE18: =(H18/$AA18)*$AB18 -> 0 | AF18: =(I18/$AA18)*$AB18 -> 0 | AG18: =(J18/$AA18)*$AB18 -> 0 | AH18: =(K18/$AA18)*$AB18 -> 0 | AI18: =(L18/$AA18)*$AB18 -> 0 | AJ18: =(M18/$AA18)*$AB18 -> 93.333333 | AK18: =(N18/$AA18)*$AB18 -> 0 | ... AW18: =(Z18/$AA18)*$AB18 -> 0 | AX18: =SUM(AF18:AW18) -> 168 | AY18: =$F18*AD18 -> 0 | AZ18: =$F18*AE18 -> 0 | BA18: =$F18*AF18 -> 0 | BB18: =$F18*AG18 -> 0 | BC18: =$F18*AH18 -> 0 | BD18: =$F18*AI18 -> 0 | BE18: =$F18*AJ18 -> 4302.6584 | BF18: =$F18*AK18 -> 0 | ... BR18: =$F18*AW18 -> 0
A19: Engel | B19: September | C19: 2025 | D19: =INDEX('Reference Sheet'!$G$9:$J$100, MATCH(A19,'Reference Sheet'!$F$9:$F$100,0), MATCH(C19,'Reference Sheet'!$G$8:$J$8,0))/2080 -> 37.647947 | E19: =VLOOKUP(C19,'Reference Sheet'!$A$2:$B$5,2) -> 0.2245 | F19: =D19*(1+E19) -> 46.099911 | M19: 100 | S19: 80 | AA19: =SUM(G19:Z19) -> 180 | AB19: =IF(OR(B19="",C19=""),"",SUMIFS('Reference Sheet'!$D$9:$D$42,'Reference Sheet'!$A$9:$A$42,C19,'Reference Sheet'!$B$9:$B$42,B19)) -> 176 | AC19: =AB19-AA19 -> -4 | AD19: =(G19/$AA19)*$AB19 -> 0 | AE19: =(H19/$AA19)*$AB19 -> 0 | AF19: =(I19/$AA19)*$AB19 -> 0 | AG19: =(J19/$AA19)*$AB19 -> 0 | AH19: =(K19/$AA19)*$AB19 -> 0 | AI19: =(L19/$AA19)*$AB19 -> 0 | AJ19: =(M19/$AA19)*$AB19 -> 97.777778 | AK19: =(N19/$AA19)*$AB19 -> 0 | ... AW19: =(Z19/$AA19)*$AB19 -> 0 | AX19: =SUM(AF19:AW19) -> 176 | AY19: =$F19*AD19 -> 0 | AZ19: =$F19*AE19 -> 0 | BA19: =$F19*AF19 -> 0 | BB19: =$F19*AG19 -> 0 | BC19: =$F19*AH19 -> 0 | BD19: =$F19*AI19 -> 0 | BE19: =$F19*AJ19 -> 4507.5469 | BF19: =$F19*AK19 -> 0 | ... BR19: =$F19*AW19 -> 0
A20: Engel | B20: October | C20: 2025 | D20: =INDEX('Reference Sheet'!$G$9:$J$100, MATCH(A20,'Reference Sheet'!$F$9:$F$100,0), MATCH(C20,'Reference Sheet'!$G$8:$J$8,0))/2080 -> 37.647947 | E20: =VLOOKUP(C20,'Reference Sheet'!$A$2:$B$5,2) -> 0.2245 | F20: =D20*(1+E20) -> 46.099911 | M20: 100 | S20: 80 | AA20: =SUM(G20:Z20) -> 180 | AB20: =IF(OR(B20="",C20=""),"",SUMIFS('Reference Sheet'!$D$9:$D$42,'Reference Sheet'!$A$9:$A$42,C20,'Reference Sheet'!$B$9:$B$42,B20)) -> 184 | AC20: =AB20-AA20 -> 4 | AD20: =(G20/$AA20)*$AB20 -> 0 | AE20: =(H20/$AA20)*$AB20 -> 0 | AF20: =(I20/$AA20)*$AB20 -> 0 | AG20: =(J20/$AA20)*$AB20 -> 0 | AH20: =(K20/$AA20)*$AB20 -> 0 | AI20: =(L20/$AA20)*$AB20 -> 0 | AJ20: =(M20/$AA20)*$AB20 -> 102.22222 | AK20: =(N20/$AA20)*$AB20 -> 0 | ... AW20: =(Z20/$AA20)*$AB20 -> 0 | AX20: =SUM(AF20:AW20) -> 184 | AY20: =$F20*AD20 -> 0 | AZ20: =$F20*AE20 -> 0 | BA20: =$F20*AF20 -> 0 | BB20: =$F20*AG20 -> 0 | BC20: =$F20*AH20 -> 0 | BD20: =$F20*AI20 -> 0 | BE20: =$F20*AJ20 -> 4712.4354 | BF20: =$F20*AK20 -> 0 | ... BR20: =$F20*AW20 -> 0
A21: Engel | B21: November | C21: 2025 | D21: =INDEX('Reference Sheet'!$G$9:$J$100, MATCH(A21,'Reference Sheet'!$F$9:$F$100,0), MATCH(C21,'Reference Sheet'!$G$8:$J$8,0))/2080 -> 37.647947 | E21: =VLOOKUP(C21,'Reference Sheet'!$A$2:$B$5,2) -> 0.2245 | F21: =D21*(1+E21) -> 46.099911 | M21: 100 | S21: 80 | AA21: =SUM(G21:Z21) -> 180 | AB21: =IF(OR(B21="",C21=""),"",SUMIFS('Reference Sheet'!$D$9:$D$42,'Reference Sheet'!$A$9:$A$42,C21,'Reference Sheet'!$B$9:$B$42,B21)) -> 160 | AC21: =AB21-AA21 -> -20 | AD21: =(G21/$AA21)*$AB21 -> 0 | AE21: =(H21/$AA21)*$AB21 -> 0 | AF21: =(I21/$AA21)*$AB21 -> 0 | AG21: =(J21/$AA21)*$AB21 -> 0 | AH21: =(K21/$AA21)*$AB21 -> 0 | AI21: =(L21/$AA21)*$AB21 -> 0 | AJ21: =(M21/$AA21)*$AB21 -> 88.888889 | AK21: =(N21/$AA21)*$AB21 -> 0 | ... AW21: =(Z21/$AA21)*$AB21 -> 0 | AX21: =SUM(AF21:AW21) -> 160 | AY21: =$F21*AD21 -> 0 | AZ21: =$F21*AE21 -> 0 | BA21: =$F21*AF21 -> 0 | BB21: =$F21*AG21 -> 0 | BC21: =$F21*AH21 -> 0 | BD21: =$F21*AI21 -> 0 | BE21: =$F21*AJ21 -> 4097.7699 | BF21: =$F21*AK21 -> 0 | ... BR21: =$F21*AW21 -> 0
A22: Engel | B22: December | C22: 2025 | D22: =INDEX('Reference Sheet'!$G$9:$J$100, MATCH(A22,'Reference Sheet'!$F$9:$F$100,0), MATCH(C22,'Reference Sheet'!$G$8:$J$8,0))/2080 -> 37.647947 | E22: =VLOOKUP(C22,'Reference Sheet'!$A$2:$B$5,2) -> 0.2245 | F22: =D22*(1+E22) -> 46.099911 | M22: 100 | S22: 80 | AA22: =SUM(G22:Z22) -> 180 | AB22: =IF(OR(B22="",C22=""),"",SUMIFS('Reference Sheet'!$D$9:$D$42,'Reference Sheet'!$A$9:$A$42,C22,'Reference Sheet'!$B$9:$B$42,B22)) -> 184 | AC22: =AB22-AA22 -> 4 | AD22: =(G22/$AA22)*$AB22 -> 0 | AE22: =(H22/$AA22)*$AB22 -> 0 | AF22: =(I22/$AA22)*$AB22 -> 0 | AG22: =(J22/$AA22)*$AB22 -> 0 | AH22: =(K22/$AA22)*$AB22 -> 0 | AI22: =(L22/$AA22)*$AB22 -> 0 | AJ22: =(M22/$AA22)*$AB22 -> 102.22222 | AK22: =(N22/$AA22)*$AB22 -> 0 | ... AW22: =(Z22/$AA22)*$AB22 -> 0 | AX22: =SUM(AF22:AW22) -> 184 | AY22: =$F22*AD22 -> 0 | AZ22: =$F22*AE22 -> 0 | BA22: =$F22*AF22 -> 0 | BB22: =$F22*AG22 -> 0 | BC22: =$F22*AH22 -> 0 | BD22: =$F22*AI22 -> 0 | BE22: =$F22*AJ22 -> 4712.4354 | BF22: =$F22*AK22 -> 0 | ... BR22: =$F22*AW22 -> 0
A23: Engel | B23: June | C23: 2025 | D23: =INDEX('Reference Sheet'!$G$9:$J$100, MATCH(A23,'Reference Sheet'!$F$9:$F$100,0), MATCH(C23,'Reference Sheet'!$G$8:$J$8,0))/2080 -> 37.647947 | E23: =VLOOKUP(C23,'Reference Sheet'!$A$2:$B$5,2) -> 0.2245 | F23: =D23*(1+E23) -> 46.099911 | M23: 100 | S23: 92 | AA23: =SUM(G23:Z23) -> 192 | AB23: =IF(OR(B23="",C23=""),"",SUMIFS('Reference Sheet'!$D$9:$D$42,'Reference Sheet'!$A$9:$A$42,C23,'Reference Sheet'!$B$9:$B$42,B23)) -> 168 | AC23: =AB23-AA23 -> -24 | AD23: =(G23/$AA23)*$AB23 -> 0 | AE23: =(H23/$AA23)*$AB23 -> 0 | AF23: =(I23/$AA23)*$AB23 -> 0 | AG23: =(J23/$AA23)*$AB23 -> 0 | AH23: =(K23/$AA23)*$AB23 -> 0 | AI23: =(L23/$AA23)*$AB23 -> 0 | AJ23: =(M23/$AA23)*$AB23 -> 87.5 | AK23: =(N23/$AA23)*$AB23 -> 0 | ... AW23: =(Z23/$AA23)*$AB23 -> 0 | AX23: =SUM(AF23:AW23) -> 168 | AY23: =$F23*AD23 -> 0 | AZ23: =$F23*AE23 -> 0 | BA23: =$F23*AF23 -> 0 | BB23: =$F23*AG23 -> 0 | BC23: =$F23*AH23 -> 0 | BD23: =$F23*AI23 -> 0 | BE23: =$F23*AJ23 -> 4033.7422 | BF23: =$F23*AK23 -> 0 | ... BR23: =$F23*AW23 -> 0
... A30: Engel | B30: July | C30: 2026 | D30: =INDEX('Reference Sheet'!$G$9:$J$100, MATCH(A30,'Reference Sheet'!$F$9:$F$100,0), MATCH(C30,'Reference Sheet'!$G$8:$J$8,0))/2080 -> 38.942308 | E30: =VLOOKUP(C30,'Reference Sheet'!$A$2:$B$5,2) -> 0.2363 | F30: =D30*(1+E30) -> 48.144375 | M30: 8 | S30: 188 | AA30: =SUM(G30:Z30) -> 196 | AB30: =IF(OR(B30="",C30=""),"",SUMIFS('Reference Sheet'!$D$9:$D$42,'Reference Sheet'!$A$9:$A$42,C30,'Reference Sheet'!$B$9:$B$42,B30)) -> 184 | AC30: =AB30-AA30 -> -12 | AD30: =(G30/$AA30)*$AB30 -> 0 | AE30: =(H30/$AA30)*$AB30 -> 0 | AF30: =(I30/$AA30)*$AB30 -> 0 | AG30: =(J30/$AA30)*$AB30 -> 0 | AH30: =(K30/$AA30)*$AB30 -> 0 | AI30: =(L30/$AA30)*$AB30 -> 0 | AJ30: =(M30/$AA30)*$AB30 -> 7.5102041 | AK30: =(N30/$AA30)*$AB30 -> 0 | ... AW30: =(Z30/$AA30)*$AB30 -> 0 | AX30: =SUM(AF30:AW30) -> 184 | AY30: =$F30*AD30 -> 0 | AZ30: =$F30*AE30 -> 0 | BA30: =$F30*AF30 -> 0 | BB30: =$F30*AG30 -> 0 | BC30: =$F30*AH30 -> 0 | BD30: =$F30*AI30 -> 0 | BE30: =$F30*AJ30 -> 361.57408 | BF30: =$F30*AK30 -> 0 | ... BR30: =$F30*AW30 -> 0
A31: Engel | B31: August | C31: 2026 | D31: =INDEX('Reference Sheet'!$G$9:$J$100, MATCH(A31,'Reference Sheet'!$F$9:$F$100,0), MATCH(C31,'Reference Sheet'!$G$8:$J$8,0))/2080 -> 38.942308 | E31: =VLOOKUP(C31,'Reference Sheet'!$A$2:$B$5,2) -> 0.2363 | F31: =D31*(1+E31) -> 48.144375 | M31: 22 | S31: 156 | AA31: =SUM(G31:Z31) -> 178 | AB31: =IF(OR(B31="",C31=""),"",SUMIFS('Reference Sheet'!$D$9:$D$44,'Reference Sheet'!$A$9:$A$44,C31,'Reference Sheet'!$B$9:$B$44,B31)) -> 176 | AC31: =AB31-AA31 -> -2 | AD31: =(G31/$AA31)*$AB31 -> 0 | AE31: =(H31/$AA31)*$AB31 -> 0 | AF31: =(I31/$AA31)*$AB31 -> 0 | AG31: =(J31/$AA31)*$AB31 -> 0 | AH31: =(K31/$AA31)*$AB31 -> 0 | AI31: =(L31/$AA31)*$AB31 -> 0 | AJ31: =(M31/$AA31)*$AB31 -> 21.752809 | AK31: =(N31/$AA31)*$AB31 -> 0 | ... AW31: =(Z31/$AA31)*$AB31 -> 0 | AX31: =SUM(AF31:AW31) -> 176 | AY31: =$F31*AD31 -> 0 | AZ31: =$F31*AE31 -> 0 | BA31: =$F31*AF31 -> 0 | BB31: =$F31*AG31 -> 0 | BC31: =$F31*AH31 -> 0 | BD31: =$F31*AI31 -> 0 | BE31: =$F31*AJ31 -> 1047.2754 | BF31: =$F31*AK31 -> 0 | ... BR31: =$F31*AW31 -> 0
A32: Ewing | B32: October | C32: 2023 | D32: =INDEX('Reference Sheet'!$G$9:$J$100, MATCH(A32,'Reference Sheet'!$F$9:$F$100,0), MATCH(C32,'Reference Sheet'!$G$8:$J$8,0))/2080 -> 71.291462 | E32: =VLOOKUP(C32,'Reference Sheet'!$A$2:$B$5,2) -> 0.2136 | F32: =D32*(1+E32) -> 86.519318 | Q32: 4.8 | AA32: =SUM(G32:Z32) -> 4.8 | AB32: =AA32 -> 4.8 | AC32: =AB32-AA32 -> 0 | AD32: =(G32/$AA32)*$AB32 -> 0 | AE32: =(H32/$AA32)*$AB32 -> 0 | AF32: =(I32/$AA32)*$AB32 -> 0 | AG32: =(J32/$AA32)*$AB32 -> 0 | AH32: =(K32/$AA32)*$AB32 -> 0 | AI32: =(L32/$AA32)*$AB32 -> 0 | AJ32: =(M32/$AA32)*$AB32 -> 0 | AK32: =(N32/$AA32)*$AB32 -> 0 | ... AW32: =(Z32/$AA32)*$AB32 -> 0 | AX32: =SUM(AF32:AW32) -> 4.8 | AY32: =$F32*AD32 -> 0 | AZ32: =$F32*AE32 -> 0 | BA32: =$F32*AF32 -> 0 | BB32: =$F32*AG32 -> 0 | BC32: =$F32*AH32 -> 0 | BD32: =$F32*AI32 -> 0 | BE32: =$F32*AJ32 -> 0 | BF32: =$F32*AK32 -> 0 | ... BR32: =$F32*AW32 -> 0
